Workbook

Sheet Water Holding Capacity
A1: Container | B1: Empty Mass | C1: Measured Soil (g) | D1: Measured Sand (g) | E1: Treatment | F1: Total Soil+Sand (g) | G1: Wet Mass (g) | H1: Oven Dry Mass (g) | I1: Expected Total Mass (g) | J1: Measured Total Mass (g) | K1: H2O Holding Capacity (mL/g dry soil)
A2: 46 | B2: 11.96 | C2: 0.999 | D2: 4 | E2: TILL | F2: =SUM(C2:D2) -> 4.999 | G2: 18.701 | H2: 16.868 | I2: =SUM(F2,B2) -> 16.959 | J2: 16.949 | K2: =((G2-H2)/F2)-0.082 -> 0.28467333
A3: 69 | B3: 12.143 | C3: 0.985 | D3: 4 | E3: TILL | F3: =SUM(C3:D3) -> 4.985 | G3: 18.826 | H3: 17.031 | I3: =SUM(F3,B3) -> 17.128 | J3: 17.11 | K3: =((G3-H3)/F3)-0.082 -> 0.27808024
A4: 78 | B4: 12.21 | C4: 1.015 | D4: 4.001 | E4: TILL | F4: =SUM(C4:D4) -> 5.016 | G4: 18.889 | H4: 17.12 | I4: =SUM(F4,B4) -> 17.226 | J4: 17.202 | K4: =((G4-H4)/F4)-0.082 -> 0.27067145
A5: 83 | B5: 12.16 | C5: 2.005 | D5: 4.001 | E5: NO TILL | F5: =SUM(C5:D5) -> 6.006 | G5: 19.163 | H5: 17.063 | I5: =SUM(F5,B5) -> 18.166 | J5: 17.15 | K5: =((G5-H5)/F5)-0.082 -> 0.26765035
A6: 99 | B6: 12.164 | C6: 0.999 | D6: 4 | E6: NO TILL | F6: =SUM(C6:D6) -> 4.999 | G6: 19.077 | H6: 17.073 | I6: =SUM(F6,B6) -> 17.163 | J6: 17.161 | K6: =((G6-H6)/F6)-0.082 -> 0.31888018
A7: 190 | B7: 12.24 | C7: 0.999 | D7: 4.001 | E7: NO TILL | F7: =SUM(C7:D7) -> 5 | G7: 19.454 | H7: 17.149 | I7: =SUM(F7,B7) -> 17.24 | J7: 17.24 | K7: =((G7-H7)/F7)-0.082 -> 0.379
A8: 202 | B8: 12.244 | C8: 1.002 | D8: 4 | E8: NTC | F8: =SUM(C8:D8) -> 5.002 | G8: 19.279 | H8: 17.143 | I8: =SUM(F8,B8) -> 17.246 | J8: 17.245 | K8: =((G8-H8)/F8)-0.082 -> 0.34502919
A9: 102 | B9: 12.168 | C9: 1.002 | D9: 4.002 | E9: NTC | F9: =SUM(C9:D9) -> 5.004 | G9: 19.169 | H9: 17.068 | I9: =SUM(F9,B9) -> 17.172 | J9: 17.171 | K9: =((G9-H9)/F9)-0.082 -> 0.33786411
A10: 143 | B10: 12.195 | C10: 1.001 | D10: 4.001 | E10: NTC | F10: =SUM(C10:D10) -> 5.002 | G10: 19.228 | H10: 17.094 | I10: =SUM(F10,B10) -> 17.197 | J10: 17.195 | K10: =((G10-H10)/F10)-0.082 -> 0.34462935
A13: 86 | B13: 12.114
A14: 174 | B14: 12.146
A15: 87 | B15: 12.129
E18: TREATMENT | F18: H2O HOLDING CAPACITY (mL/ g dry soil+sand)
E19: TILL | F19: =AVERAGE(K2:K4) -> 0.27780834
E20: NO TILL | F20: =AVERAGE(K5:K7) -> 0.32184351
E21: NTC | F21: =AVERAGE(K8:K10) -> 0.34250755

Sheet Template
B1: 区・条件 | C1: STD ppm | F1: year | G1: month | H1: day | I1: hh | J1: mm | K1: ss | L1: sample number | M1: CO2rt | N1: CO2hi | O1: CO2area | P1: 右は計算領域 | Q1: CO2(ppm)初期標準 | R1: ドリフト時計算 | S1: 絶対時間（ｈ） | T1: ドリフトstd factor | U1: CO2(ppm)
C2: CO2 0.9047% | D2: sample前 | F2: 2013 | G2: 7 | S2: =H2*24+I2+J2/60+K2/3600 -> 0
B3: CO２ | C3: CO2 0.9047% | D3: sample前 | F3: 2013 | G3: 7 | S3: =H3*24+I3+J3/60+K3/3600 -> 0
B4: 9047 | C4: CO2 0.9047% | D4: sample前 | F4: 2013 | G4: 7 | S4: =H4*24+I4+J4/60+K4/3600 -> 0
C5: CO2 0.9047% | D5: sample前 | F5: 2013 | G5: 7
C7: CO2 0.9047% | D7: sample後 | F7: 2013 | G7: 7 | S7: =H7*24+I7+J7/60+K7/3600 -> 0
C8: CO2 0.9047% | D8: sample後 | F8: 2013 | G8: 7 | S8: =H8*24+I8+J8/60+K8/3600 -> 0
C9: CO2 0.9047% | D9: sample後 | F9: 2013 | G9: 7 | S9: =H9*24+I9+J9/60+K9/3600 -> 0
C10: CO2 0.9047% | D10: sample後 | F10: 2013 | G10: 7
B14: 標準パラメータ | Q14: factor
C15: CO2濃度 | D15: CO2 | F15: 9047 | G15: ppm | H15: 前 | M15: =AVERAGE(M2:M6) -> #DIV/0! | N15: =AVERAGE(N2:N6) -> #DIV/0! | O15: =AVERAGE(O2:O6) -> #DIV/0! | Q15: =F15/O15 -> #DIV/0! | S15: =AVERAGE(S2:S6) -> 0
H16: 後 | M16: =AVERAGE(M7:M11) -> #DIV/0! | N16: =AVERAGE(N7:N11) -> #DIV/0! | O16: =AVERAGE(O7:O11) -> #DIV/0! | Q16: =F15/O16 -> #DIV/0! | S16: =AVERAGE(S7:S11) -> 0
Q18: 初期std利用 | U18: ドリフト補正有
B19: 15 deg | C19: 1 | F19: 2013 | G19: 7 | Q19: =O19*$Q$15 -> #DIV/0! | S19: =H19*24+I19+J19/60+K19/3600 -> 0 | T19: =Q15+(Q16-Q15)*(S19-S15)/(S16-S15) -> #DIV/0! | U19: =O19*T19 -> #DIV/0!
C20: 2 | F20: 2013 | G20: 7 | Q20: =O20*$Q$15 -> #DIV/0! | S20: =H20*24+I20+J20/60+K20/3600 -> 0 | T20: =Q15+(Q16-Q15)*(S20-S15)/(S16-S15) -> #DIV/0! | U20: =O20*T20 -> #DIV/0!
C21: 3 | F21: 2013 | G21: 7 | Q21: =O21*$Q$15 -> #DIV/0! | S21: =H21*24+I21+J21/60+K21/3600 -> 0 | T21: =Q15+(Q16-Q15)*(S21-S15)/(S16-S15) -> #DIV/0! | U21: =O21*T21 -> #DIV/0!
C22: 4 | F22: 2013 | G22: 7 | Q22: =O22*$Q$15 -> #DIV/0! | S22: =H22*24+I22+J22/60+K22/3600 -> 0 | T22: =Q15+(Q16-Q15)*(S22-S15)/(S16-S15) -> #DIV/0! | U22: =O22*T22 -> #DIV/0!
C23: 5 | F23: 2013 | G23: 7 | Q23: =O23*$Q$15 -> #DIV/0! | S23: =H23*24+I23+J23/60+K23/3600 -> 0 | T23: =Q15+(Q16-Q15)*(S23-S15)/(S16-S15) -> #DIV/0! | U23: =O23*T23 -> #DIV/0!
C24: 6 | F24: 2013 | G24: 7 | Q24: =O24*$Q$15 -> #DIV/0! | S24: =H24*24+I24+J24/60+K24/3600 -> 0 | T24: =Q15+(Q16-Q15)*(S24-S15)/(S16-S15) -> #DIV/0! | U24: =O24*T24 -> #DIV/0!
C25: 7 | F25: 2013 | G25: 7 | Q25: =O25*$Q$15 -> #DIV/0! | S25: =H25*24+I25+J25/60+K25/3600 -> 0 | T25: =Q15+(Q16-Q15)*(S25-S15)/(S16-S15) -> #DIV/0! | U25: =O25*T25 -> #DIV/0!
C26: 8 | F26: 2013 | G26: 7 | Q26: =O26*$Q$15 -> #DIV/0! | S26: =H26*24+I26+J26/60+K26/3600 -> 0 | T26: =Q15+(Q16-Q15)*(S26-S15)/(S16-S15) -> #DIV/0! | U26: =O26*T26 -> #DIV/0!
C27: 9 | F27: 2013 | G27: 7 | Q27: =O27*$Q$15 -> #DIV/0! | S27: =H27*24+I27+J27/60+K27/3600 -> 0 | T27: =Q15+(Q16-Q15)*(S27-S15)/(S16-S15) -> #DIV/0! | U27: =O27*T27 -> #DIV/0!
C28: 10 | F28: 2013 | G28: 7 | Q28: =O28*$Q$15 -> #DIV/0! | S28: =H28*24+I28+J28/60+K28/3600 -> 0 | T28: =Q15+(Q16-Q15)*(S28-S15)/(S16-S15) -> #DIV/0! | U28: =O28*T28 -> #DIV/0!
C29: 12 | F29: 2013 | G29: 7 | Q29: =O29*$Q$15 -> #DIV/0! | S29: =H29*24+I29+J29/60+K29/3600 -> 0 | T29: =Q15+(Q16-Q15)*(S29-S15)/(S16-S15) -> #DIV/0! | U29: =O29*T29 -> #DIV/0!
C30: 13 | F30: 2013 | G30: 7 | Q30: =O30*$Q$15 -> #DIV/0! | S30: =H30*24+I30+J30/60+K30/3600 -> 0 | T30: =Q15+(Q16-Q15)*(S30-S15)/(S16-S15) -> #DIV/0! | U30: =O30*T30 -> #DIV/0!
C31: 14 | F31: 2013 | G31: 7 | Q31: =O31*$Q$15 -> #DIV/0! | S31: =H31*24+I31+J31/60+K31/3600 -> 0 | T31: =Q15+(Q16-Q15)*(S31-S15)/(S16-S15) -> #DIV/0! | U31: =O31*T31 -> #DIV/0!
C32: 85 | F32: 2013 | G32: 7 | Q32: =O32*$Q$15 -> #DIV/0! | S32: =H32*24+I32+J32/60+K32/3600 -> 0 | T32: =Q15+(Q16-Q15)*(S32-S15)/(S16-S15) -> #DIV/0! | U32: =O32*T32 -> #DIV/0!
C33: 15 | F33: 2013 | G33: 7 | Q33: =O33*$Q$15 -> #DIV/0! | S33: =H33*24+I33+J33/60+K33/3600 -> 0 | T33: =Q15+(Q16-Q15)*(S33-S15)/(S16-S15) -> #DIV/0! | U33: =O33*T33 -> #DIV/0!
C34: 16 | F34: 2013 | G34: 7 | Q34: =O34*$Q$15 -> #DIV/0! | S34: =H34*24+I34+J34/60+K34/3600 -> 0 | T34: =Q15+(Q16-Q15)*(S34-S15)/(S16-S15) -> #DIV/0! | U34: =O34*T34 -> #DIV/0!
C35: 17 | F35: 2013 | G35: 7 | Q35: =O35*$Q$15 -> #DIV/0! | S35: =H35*24+I35+J35/60+K35/3600 -> 0 | T35: =Q15+(Q16-Q15)*(S35-S15)/(S16-S15) -> #DIV/0! | U35: =O35*T35 -> #DIV/0!
C36: 18 | F36: 2013 | G36: 7 | Q36: =O36*$Q$15 -> #DIV/0! | S36: =H36*24+I36+J36/60+K36/3600 -> 0 | T36: =Q15+(Q16-Q15)*(S36-S15)/(S16-S15) -> #DIV/0! | U36: =O36*T36 -> #DIV/0!
C37: 19 | F37: 2013 | G37: 7 | Q37: =O37*$Q$15 -> #DIV/0! | S37: =H37*24+I37+J37/60+K37/3600 -> 0 | T37: =Q15+(Q16-Q15)*(S37-S15)/(S16-S15) -> #DIV/0! | U37: =O37*T37 -> #DIV/0!
C38: 20 | F38: 2013 | G38: 7 | Q38: =O38*$Q$15 -> #DIV/0! | S38: =H38*24+I38+J38/60+K38/3600 -> 0 | T38: =Q15+(Q16-Q15)*(S38-S15)/(S16-S15) -> #DIV/0! | U38: =O38*T38 -> #DIV/0!
C39: 21 | F39: 2013 | G39: 7 | Q39: =O39*$Q$15 -> #DIV/0! | S39: =H39*24+I39+J39/60+K39/3600 -> 0 | T39: =Q15+(Q16-Q15)*(S39-S15)/(S16-S15) -> #DIV/0! | U39: =O39*T39 -> #DIV/0!
C40: 22 | F40: 2013 | G40: 7 | Q40: =O40*$Q$15 -> #DIV/0! | S40: =H40*24+I40+J40/60+K40/3600 -> 0 | T40: =Q15+(Q16-Q15)*(S40-S15)/(S16-S15) -> #DIV/0! | U40: =O40*T40 -> #DIV/0!
C41: 23 | F41: 2013 | G41: 7 | Q41: =O41*$Q$15 -> #DIV/0! | S41: =H41*24+I41+J41/60+K41/3600 -> 0 | T41: =Q15+(Q16-Q15)*(S41-S15)/(S16-S15) -> #DIV/0! | U41: =O41*T41 -> #DIV/0!
C42: 24 | F42: 2013 | G42: 7 | Q42: =O42*$Q$15 -> #DIV/0! | S42: =H42*24+I42+J42/60+K42/3600 -> 0 | T42: =Q15+(Q16-Q15)*(S42-S15)/(S16-S15) -> #DIV/0! | U42: =O42*T42 -> #DIV/0!
C43: 25 | F43: 2013 | G43: 7 | Q43: =O43*$Q$15 -> #DIV/0! | S43: =H43*24+I43+J43/60+K43/3600 -> 0 | T43: =Q15+(Q16-Q15)*(S43-S15)/(S16-S15) -> #DIV/0! | U43: =O43*T43 -> #DIV/0!
C44: 26 | F44: 2013 | G44: 7 | Q44: =O44*$Q$15 -> #DIV/0! | S44: =H44*24+I44+J44/60+K44/3600 -> 0 | T44: =Q15+(Q16-Q15)*(S44-S15)/(S16-S15) -> #DIV/0! | U44: =O44*T44 -> #DIV/0!
C45: 27 | F45: 2013 | G45: 7 | Q45: =O45*$Q$15 -> #DIV/0! | S45: =H45*24+I45+J45/60+K45/3600 -> 0 | T45: =Q15+(Q16-Q15)*(S45-S15)/(S16-S15) -> #DIV/0! | U45: =O45*T45 -> #DIV/0!
...

Sheet Experimental Info and Setup
A1: Jar # | B1: Soil Type | C1: Temp (deg C) | D1: Treatment | E1: Replicate # | F1: Jar+Lid Mass (g) | G1: Soil Mass (g) | H1: Sand Mass (g) | I1: Total Dry Mass (g) | J1: H2O holding capacity (Ml/g) | K1: Water to make 60% H.Cap. (mL) | L1: Bacterial Inoculum (mL) | M1: Amoebal Inoculum (Ml) | N1: Sterile H2O [to add] | O1: Wet Mass (60% Cap.) expected | P1: Wet Mass Observed 7/22 before 15 deg | Q1: moisture difference | R1: Expected soil+jar+lid mass | S1: Measured soil+jar+lid mass | T1: Minus this amt. of H2O | U1: amoeabe added 7/24 | V1: water added 7/24 | X1: Sterile H2O added 7/18 | Y1: Current Mass (7/19) (too high) | Z1: Difference (need to lose)
A2: 1 | B2: TILL | C2: 15 | D2: B+A | E2: 1 | F2: 57.562 | G2: 3 | H2: 12 | I2: =SUM(G2:H2) -> 15 | J2: 0.27780834 | K2: =(J2*I2)*0.6 -> 2.5002751 | L2: 2 | M2: 0.5 | N2: =K2-(L2+M2) -> 0.00027508023 | O2: =I2+K2+F2 -> 75.062275 | P2: 75.09 | Q2: =O2-P2 -> -0.02772492 | T2: =S2-R2 -> 0 | U2: y | X2: 3 | Z2: =(Y2-O2)+0.25 -> -74.812275
A3: 2 | B3: TILL | C3: 15 | D3: B+A | E3: 2 | F3: 57.573 | G3: 3 | H3: 12 | I3: =SUM(G3:H3) -> 15 | J3: 0.27780834 | K3: =(J3*I3)*0.6 -> 2.5002751 | L3: 2 | M3: 0.5 | N3: =K3-(L3+M3) -> 0.00027508023 | O3: =I3+K3+F3 -> 75.073275 | P3: 75.1 | Q3: =O3-P3 -> -0.02672492 | T3: =S3-R3 -> 0 | U3: y | X3: 3 | Z3: =(Y3-O3)+0.25 -> -74.823275 | AT3: Initial N readings | AV3: 41479
A4: 3 | B4: TILL | C4: 15 | D4: B+A | E4: 3 | F4: 59.277 | G4: 3 | H4: 12 | I4: =SUM(G4:H4) -> 15 | J4: 0.27780834 | K4: =(J4*I4)*0.6 -> 2.5002751 | L4: 2 | M4: 0.5 | N4: =K4-(L4+M4) -> 0.00027508023 | O4: =I4+K4+F4 -> 76.777275 | P4: 76.8 | Q4: =O4-P4 -> -0.02272492 | T4: =S4-R4 -> 0 | U4: y | X4: 3 | Z4: =(Y4-O4)+0.25 -> -76.527275 | AT4: Soil Type | AU4: Community | AV4: Jar
A5: 4 | B5: TILL | C5: 15 | D5: B+A | E5: 4 | F5: 57.995 | G5: 3 | H5: 12 | I5: =SUM(G5:H5) -> 15 | J5: 0.27780834 | K5: =(J5*I5)*0.6 -> 2.5002751 | L5: 2 | M5: 0.5 | N5: =K5-(L5+M5) -> 0.00027508023 | O5: =I5+K5+F5 -> 75.495275 | P5: 75.51 | Q5: =O5-P5 -> -0.01472492 | T5: =S5-R5 -> 0 | U5: y | X5: 3 | Z5: =(Y5-O5)+0.25 -> -75.245275 | AT5: Till | AU5: Bac | AV5: 86
A6: 5 | B6: TILL | C6: 15 | D6: B+A | E6: 5 | F6: 58.243 | G6: 3 | H6: 12 | I6: =SUM(G6:H6) -> 15 | J6: 0.27780834 | K6: =(J6*I6)*0.6 -> 2.5002751 | L6: 2 | M6: 0.5 | N6: =K6-(L6+M6) -> 0.00027508023 | O6: =I6+K6+F6 -> 75.743275 | P6: 75.72 | Q6: =O6-P6 -> 0.02327508 | T6: =S6-R6 -> 0 | U6: y | X6: 3 | Z6: =(Y6-O6)+0.25 -> -75.493275 | AT6: Till | AU6: Bac | AV6: 87
A7: 6 | B7: TILL | C7: 15 | D7: B | E7: 1 | F7: 58.338 | G7: 3 | H7: 12 | I7: =SUM(G7:H7) -> 15 | J7: 0.27780834 | K7: =(J7*I7)*0.6 -> 2.5002751 | L7: 2 | M7: 0 | N7: =K7-(L7+M7) -> 0.50027508 | O7: =I7+K7+F7 -> 75.838275 | P7: 75.86 | Q7: =O7-P7 -> -0.02172492 | T7: =S7-R7 -> 0 | X7: 3 | Z7: =(Y7-O7)+0.25 -> -75.588275 | AT7: Till | AU7: Bac | AV7: 88
A8: 7 | B8: TILL | C8: 15 | D8: B | E8: 2 | F8: 57.756 | G8: 3 | H8: 12 | I8: =SUM(G8:H8) -> 15 | J8: 0.27780834 | K8: =(J8*I8)*0.6 -> 2.5002751 | L8: 2 | M8: 0 | N8: =K8-(L8+M8) -> 0.50027508 | O8: =I8+K8+F8 -> 75.256275 | P8: 75.27 | Q8: =O8-P8 -> -0.01372492 | T8: =S8-R8 -> 0 | X8: 3 | Z8: =(Y8-O8)+0.25 -> -75.006275 | AT8: Till | AU8: Sterile | AV8: 93
A9: 8 | B9: TILL | C9: 15 | D9: B | E9: 3 | F9: 57.906 | G9: 3 | H9: 12 | I9: =SUM(G9:H9) -> 15 | J9: 0.27780834 | K9: =(J9*I9)*0.6 -> 2.5002751 | L9: 2 | M9: 0 | N9: =K9-(L9+M9) -> 0.50027508 | O9: =I9+K9+F9 -> 75.406275 | P9: 75.41 | Q9: =O9-P9 -> -0.0037249198 | T9: =S9-R9 -> 0 | X9: 3 | Z9: =(Y9-O9)+0.25 -> -75.156275 | AT9: Till | AU9: Sterile | AV9: 94
A10: 9 | B10: TILL | C10: 15 | D10: B | E10: 4 | F10: 57.778 | G10: 3 | H10: 12 | I10: =SUM(G10:H10) -> 15 | J10: 0.27780834 | K10: =(J10*I10)*0.6 -> 2.5002751 | L10: 2 | M10: 0 | N10: =K10-(L10+M10) -> 0.50027508 | O10: =I10+K10+F10 -> 75.278275 | P10: 75.29 | Q10: =O10-P10 -> -0.01172492 | T10: =S10-R10 -> 0 | X10: 3 | Z10: =(Y10-O10)+0.25 -> -75.028275 | AT10: Till | AU10: Sterile | AV10: 95
A11: 10 | B11: TILL | C11: 15 | D11: B | E11: 5 | F11: 58.732 | G11: 3 | H11: 12 | I11: =SUM(G11:H11) -> 15 | J11: 0.27780834 | K11: =(J11*I11)*0.6 -> 2.5002751 | L11: 2 | M11: 0 | N11: =K11-(L11+M11) -> 0.50027508 | O11: =I11+K11+F11 -> 76.232275 | P11: 76.23 | Q11: =O11-P11 -> 0.0022750802 | T11: =S11-R11 -> 0 | X11: 3 | Z11: =(Y11-O11)+0.25 -> -75.982275 | AC11: need to weigh jars on Monday. Hopefully they will have dried down in mass and the new amount can be added back Monday or Tuesday. | AT11: NoTill | AU11: Bac | AV11: 89
A12: 85 | B12: TILL | C12: 15 | D12: S | E12: 1 | F12: 58.667 | G12: 3 | H12: 12 | I12: =SUM(G12:H12) -> 15 | J12: 0.27780834 | K12: =(J12*I12)*0.6 -> 2.5002751 | L12: 0 | M12: 0 | N12: =K12-(L12+M12) -> 2.5002751 | O12: =I12+K12+F12 -> 76.167275 | P12: 75.06 | Q12: =O12-P12 -> 1.1072751 | T12: =S12-R12 -> 0 | X12: 3 | Z12: =(Y12-O12)+0.25 -> -75.917275 | AT12: NoTill | AU12: Bac | AV12: 90
A13: 12 | B13: TILL | C13: 15 | D13: N | E13: 2 | F13: 58.732 | G13: 3 | H13: 12 | I13: =SUM(G13:H13) -> 15 | J13: 0.27780834 | K13: =(J13*I13)*0.6 -> 2.5002751 | L13: 0 | M13: 0 | N13: =K13-(L13+M13) -> 2.5002751 | O13: =I13+K13+F13 -> 76.232275 | P13: 76.26 | Q13: =O13-P13 -> -0.02772492 | T13: =S13-R13 -> 0 | X13: 3 | Z13: =(Y13-O13)+0.25 -> -75.982275 | AT13: NoTill | AU13: Bac | AV13: 91
A14: 13 | B14: TILL | C14: 15 | D14: N | E14: 3 | F14: 58.172 | G14: 3 | H14: 12 | I14: =SUM(G14:H14) -> 15 | J14: 0.27780834 | K14: =(J14*I14)*0.6 -> 2.5002751 | L14: 0 | M14: 0 | N14: =K14-(L14+M14) -> 2.5002751 | O14: =I14+K14+F14 -> 75.672275 | P14: 75.69 | Q14: =O14-P14 -> -0.01772492 | T14: =S14-R14 -> 0 | X14: 3 | Z14: =(Y14-O14)+0.25 -> -75.422275 | AT14: NoTill | AU14: Sterile | AV14: 92
A15: 14 | B15: TILL | C15: 15 | D15: N | E15: 1 | F15: 57.993 | G15: 3 | H15: 12 | I15: =SUM(G15:H15) -> 15 | J15: 0.27780834 | K15: =(J15*I15)*0.6 -> 2.5002751 | L15: 0 | M15: 0 | N15: =K15-(L15+M15) -> 2.5002751 | O15: =I15+K15+F15 -> 75.493275 | P15: 75.52 | Q15: =O15-P15 -> -0.02672492 | T15: =S15-R15 -> 0 | X15: 3 | Z15: =(Y15-O15)+0.25 -> -75.243275 | AT15: NoTill | AU15: Sterile | AV15: 96
A16: 15 | B16: NO TILL | C16: 15 | D16: B+A | E16: 1 | F16: 59.313 | G16: 3 | H16: 12 | I16: =SUM(G16:H16) -> 15 | J16: 0.32184351 | K16: =(J16*I16)*0.6 -> 2.8965916 | L16: 2 | M16: 0.5 | N16: =K16-(L16+M16) -> 0.39659158 | O16: =I16+K16+F16 -> 77.209592 | P16: 77.19 | Q16: =O16-P16 -> 0.019591577 | T16: =S16-R16 -> 0 | U16: y | X16: 3 | Z16: =(Y16-O16)+0.25 -> -76.959592 | AT16: NoTill | AU16: Sterile | AV16: 97
A17: 16 | B17: NO TILL | C17: 15 | D17: B+A | E17: 2 | F17: 59.31 | G17: 3 | H17: 12 | I17: =SUM(G17:H17) -> 15 | J17: 0.32184351 | K17: =(J17*I17)*0.6 -> 2.8965916 | L17: 2 | M17: 0.5 | N17: =K17-(L17+M17) -> 0.39659158 | O17: =I17+K17+F17 -> 77.206592 | P17: 77.17 | Q17: =O17-P17 -> 0.036591577 | T17: =S17-R17 -> 0 | U17: y | X17: 3 | Z17: =(Y17-O17)+0.25 -> -76.956592 | AT17: Blank | AU17: - | AV17: Bl1
A18: 17 | B18: NO TILL | C18: 15 | D18: B+A | E18: 3 | F18: 59.258 | G18: 3 | H18: 12 | I18: =SUM(G18:H18) -> 15 | J18: 0.32184351 | K18: =(J18*I18)*0.6 -> 2.8965916 | L18: 2 | M18: 0.5 | N18: =K18-(L18+M18) -> 0.39659158 | O18: =I18+K18+F18 -> 77.154592 | P18: 77.12 | Q18: =O18-P18 -> 0.034591577 | T18: =S18-R18 -> 0 | U18: y | X18: 3 | Z18: =(Y18-O18)+0.25 -> -76.904592 | AT18: Blank | AU18: - | AV18: Bl2
A19: 18 | B19: NO TILL | C19: 15 | D19: B+A | E19: 4 | F19: 58.044 | G19: 3 | H19: 12 | I19: =SUM(G19:H19) -> 15 | J19: 0.32184351 | K19: =(J19*I19)*0.6 -> 2.8965916 | L19: 2 | M19: 0.5 | N19: =K19-(L19+M19) -> 0.39659158 | O19: =I19+K19+F19 -> 75.940592 | P19: 75.98 | Q19: =O19-P19 -> -0.039408423 | T19: =S19-R19 -> 0 | U19: y | X19: 3 | Z19: =(Y19-O19)+0.25 -> -75.690592 | AT19: Blank | AU19: - | AV19: Bl3
A20: 19 | B20: NO TILL | C20: 15 | D20: B+A | E20: 5 | F20: 59.353 | G20: 3 | H20: 12 | I20: =SUM(G20:H20) -> 15 | J20: 0.32184351 | K20: =(J20*I20)*0.6 -> 2.8965916 | L20: 2 | M20: 0.5 | N20: =K20-(L20+M20) -> 0.39659158 | O20: =I20+K20+F20 -> 77.249592 | P20: 77.28 | Q20: =O20-P20 -> -0.030408423 | T20: =S20-R20 -> 0 | U20: y | X20: 3 | Z20: =(Y20-O20)+0.25 -> -76.999592
A21: 20 | B21: NO TILL | C21: 15 | D21: B | E21: 1 | F21: 57.832 | G21: 3 | H21: 12 | I21: =SUM(G21:H21) -> 15 | J21: 0.32184351 | K21: =(J21*I21)*0.6 -> 2.8965916 | L21: 2 | M21: 0 | N21: =K21-(L21+M21) -> 0.89659158 | O21: =I21+K21+F21 -> 75.728592 | P21: 75.73 | Q21: =O21-P21 -> -0.0014084229 | T21: =S21-R21 -> 0 | X21: 3 | Z21: =(Y21-O21)+0.25 -> -75.478592
A22: 21 | B22: NO TILL | C22: 15 | D22: B | E22: 2 | F22: 57.781 | G22: 3 | H22: 12 | I22: =SUM(G22:H22) -> 15 | J22: 0.32184351 | K22: =(J22*I22)*0.6 -> 2.8965916 | L22: 2 | M22: 0 | N22: =K22-(L22+M22) -> 0.89659158 | O22: =I22+K22+F22 -> 75.677592 | P22: 75.68 | Q22: =O22-P22 -> -0.0024084229 | T22: =S22-R22 -> 0 | X22: 3 | Z22: =(Y22-O22)+0.25 -> -75.427592
A23: 22 | B23: NO TILL | C23: 15 | D23: B | E23: 3 | F23: 59.121 | G23: 3 | H23: 12 | I23: =SUM(G23:H23) -> 15 | J23: 0.32184351 | K23: =(J23*I23)*0.6 -> 2.8965916 | L23: 2 | M23: 0 | N23: =K23-(L23+M23) -> 0.89659158 | O23: =I23+K23+F23 -> 77.017592 | P23: 77.05 | Q23: =O23-P23 -> -0.032408423 | T23: =S23-R23 -> 0 | X23: 3 | Z23: =(Y23-O23)+0.25 -> -76.767592
A24: 23 | B24: NO TILL | C24: 15 | D24: B | E24: 4 | F24: 57.805 | G24: 3 | H24: 12 | I24: =SUM(G24:H24) -> 15 | J24: 0.32184351 | K24: =(J24*I24)*0.6 -> 2.8965916 | L24: 2 | M24: 0 | N24: =K24-(L24+M24) -> 0.89659158 | O24: =I24+K24+F24 -> 75.701592 | P24: 75.71 | Q24: =O24-P24 -> -0.0084084229 | T24: =S24-R24 -> 0 | X24: 3 | Z24: =(Y24-O24)+0.25 -> -75.451592
A25: 24 | B25: NO TILL | C25: 15 | D25: B | E25: 5 | F25: 57.324 | G25: 3 | H25: 12 | I25: =SUM(G25:H25) -> 15 | J25: 0.32184351 | K25: =(J25*I25)*0.6 -> 2.8965916 | L25: 2 | M25: 0 | N25: =K25-(L25+M25) -> 0.89659158 | O25: =I25+K25+F25 -> 75.220592 | P25: 75.23 | Q25: =O25-P25 -> -0.0094084229 | T25: =S25-R25 -> 0 | X25: 3 | Z25: =(Y25-O25)+0.25 -> -74.970592
A26: 25 | B26: NO TILL | C26: 15 | D26: N | E26: 1 | F26: 59.082 | G26: 3 | H26: 12 | I26: =SUM(G26:H26) -> 15 | J26: 0.32184351 | K26: =(J26*I26)*0.6 -> 2.8965916 | L26: 0 | M26: 0 | N26: =K26-(L26+M26) -> 2.8965916 | O26: =I26+K26+F26 -> 76.978592 | P26: 77.38 | Q26: =O26-P26 -> -0.40140842 | T26: =S26-R26 -> 0 | X26: 3 | Z26: =(Y26-O26)+0.25 -> -76.728592
A27: 26 | B27: NO TILL | C27: 15 | D27: N | E27: 2 | F27: 59.485 | G27: 3 | H27: 12 | I27: =SUM(G27:H27) -> 15 | J27: 0.32184351 | K27: =(J27*I27)*0.6 -> 2.8965916 | L27: 0 | M27: 0 | N27: =K27-(L27+M27) -> 2.8965916 | O27: =I27+K27+F27 -> 77.381592 | P27: 77.32 | Q27: =O27-P27 -> 0.061591577 | T27: =S27-R27 -> 0 | X27: 3 | Z27: =(Y27-O27)+0.25 -> -77.131592
A28: 27 | B28: NO TILL | C28: 15 | D28: N | E28: 3 | F28: 59.258 | G28: 3 | H28: 12 | I28: =SUM(G28:H28) -> 15 | J28: 0.32184351 | K28: =(J28*I28)*0.6 -> 2.8965916 | L28: 0 | M28: 0 | N28: =K28-(L28+M28) -> 2.8965916 | O28: =I28+K28+F28 -> 77.154592 | P28: 77.79 | Q28: =O28-P28 -> -0.63540842 | T28: =S28-R28 -> 0 | X28: 3 | Z28: =(Y28-O28)+0.25 -> -76.904592
A29: 28 | B29: NO TILL | C29: 15 | D29: S | E29: 1 | F29: 59.252 | G29: 3 | H29: 12 | I29: =SUM(G29:H29) -> 15 | J29: 0.32184351 | K29: =(J29*I29)*0.6 -> 2.8965916 | L29: 0 | M29: 0 | N29: =K29-(L29+M29) -> 2.8965916 | O29: =I29+K29+F29 -> 77.148592 | P29: 77.14 | Q29: =O29-P29 -> 0.0085915771 | T29: =S29-R29 -> 0 | X29: 3 | Z29: =(Y29-O29)+0.25 -> -76.898592
A30: 29 | B30: NT CRUSH | C30: 15 | D30: B+A | E30: 1 | F30: 58.177 | G30: 3 | H30: 12 | I30: =SUM(G30:H30) -> 15 | J30: 0.34250755 | K30: =(J30*I30)*0.6 -> 3.0825679 | L30: 2 | M30: 0.5 | N30: =K30-(L30+M30) -> 0.58256794 | O30: =I30+K30+F30 -> 76.259568 | P30: 75.33 | Q30: =O30-P30 -> 0.92956794 | T30: =S30-R30 -> 0 | U30: y | X30: 3 | Z30: =(Y30-O30)+0.25 -> -76.009568
A31: 30 | B31: NT CRUSH | C31: 15 | D31: B+A | E31: 2 | F31: 58.045 | G31: 3 | H31: 12 | I31: =SUM(G31:H31) -> 15 | J31: 0.34250755 | K31: =(J31*I31)*0.6 -> 3.0825679 | L31: 2 | M31: 0.5 | N31: =K31-(L31+M31) -> 0.58256794 | O31: =I31+K31+F31 -> 76.127568 | P31: 76.17 | Q31: =O31-P31 -> -0.042432064 | T31: =S31-R31 -> 0 | U31: y | X31: 3 | Z31: =(Y31-O31)+0.25 -> -75.877568
A32: 31 | B32: NT CRUSH | C32: 15 | D32: B+A | E32: 3 | F32: 58.694 | G32: 3 | H32: 12 | I32: =SUM(G32:H32) -> 15 | J32: 0.34250755 | K32: =(J32*I32)*0.6 -> 3.0825679 | L32: 2 | M32: 0.5 | N32: =K32-(L32+M32) -> 0.58256794 | O32: =I32+K32+F32 -> 76.776568 | P32: 76.82 | Q32: =O32-P32 -> -0.043432064 | T32: =S32-R32 -> 0 | U32: y | X32: 3 | Z32: =(Y32-O32)+0.25 -> -76.526568
A33: 32 | B33: NT CRUSH | C33: 15 | D33: B+A | E33: 4 | F33: 57.306 | G33: 3 | H33: 12 | I33: =SUM(G33:H33) -> 15 | J33: 0.34250755 | K33: =(J33*I33)*0.6 -> 3.0825679 | L33: 2 | M33: 0.5 | N33: =K33-(L33+M33) -> 0.58256794 | O33: =I33+K33+F33 -> 75.388568 | P33: 75.4 | Q33: =O33-P33 -> -0.011432064 | T33: =S33-R33 -> 0 | U33: y | X33: 3 | Z33: =(Y33-O33)+0.25 -> -75.138568
A34: 33 | B34: NT CRUSH | C34: 15 | D34: B+A | E34: 5 | F34: 58.787 | G34: 3 | H34: 12 | I34: =SUM(G34:H34) -> 15 | J34: 0.34250755 | K34: =(J34*I34)*0.6 -> 3.0825679 | L34: 2 | M34: 0.5 | N34: =K34-(L34+M34) -> 0.58256794 | O34: =I34+K34+F34 -> 76.869568 | P34: 76.88 | Q34: =O34-P34 -> -0.010432064 | T34: =S34-R34 -> 0 | U34: y | X34: 3 | Z34: =(Y34-O34)+0.25 -> -76.619568
A35: 34 | B35: NT CRUSH | C35: 15 | D35: B | E35: 1 | F35: 58.746 | G35: 3 | H35: 12 | I35: =SUM(G35:H35) -> 15 | J35: 0.34250755 | K35: =(J35*I35)*0.6 -> 3.0825679 | L35: 2 | M35: 0 | N35: =K35-(L35+M35) -> 1.0825679 | O35: =I35+K35+F35 -> 76.828568 | P35: 76.84 | Q35: =O35-P35 -> -0.011432064 | T35: =S35-R35 -> 0 | X35: 3 | Z35: =(Y35-O35)+0.25 -> -76.578568
A36: 35 | B36: NT CRUSH | C36: 15 | D36: B | E36: 2 | F36: 59.216 | G36: 3 | H36: 12 | I36: =SUM(G36:H36) -> 15 | J36: 0.34250755 | K36: =(J36*I36)*0.6 -> 3.0825679 | L36: 2 | M36: 0 | N36: =K36-(L36+M36) -> 1.0825679 | O36: =I36+K36+F36 -> 77.298568 | P36: 77.28 | Q36: =O36-P36 -> 0.018567936 | T36: =S36-R36 -> 0 | X36: 3 | Z36: =(Y36-O36)+0.25 -> -77.048568
A37: 36 | B37: NT CRUSH | C37: 15 | D37: B | E37: 3 | F37: 57.85 | G37: 3 | H37: 12 | I37: =SUM(G37:H37) -> 15 | J37: 0.34250755 | K37: =(J37*I37)*0.6 -> 3.0825679 | L37: 2 | M37: 0 | N37: =K37-(L37+M37) -> 1.0825679 | O37: =I37+K37+F37 -> 75.932568 | P37: 75.93 | Q37: =O37-P37 -> 0.0025679359 | T37: =S37-R37 -> 0 | X37: 3 | Z37: =(Y37-O37)+0.25 -> -75.682568
A38: 37 | B38: NT CRUSH | C38: 15 | D38: B | E38: 4 | F38: 59.211 | G38: 3 | H38: 12 | I38: =SUM(G38:H38) -> 15 | J38: 0.34250755 | K38: =(J38*I38)*0.6 -> 3.0825679 | L38: 2 | M38: 0 | N38: =K38-(L38+M38) -> 1.0825679 | O38: =I38+K38+F38 -> 77.293568 | P38: 77.32 | Q38: =O38-P38 -> -0.026432064 | T38: =S38-R38 -> 0 | X38: 3 | Z38: =(Y38-O38)+0.25 -> -77.043568
A39: 38 | B39: NT CRUSH | C39: 15 | D39: B | E39: 5 | F39: 58.795 | G39: 3 | H39: 12 | I39: =SUM(G39:H39) -> 15 | J39: 0.34250755 | K39: =(J39*I39)*0.6 -> 3.0825679 | L39: 2 | M39: 0 | N39: =K39-(L39+M39) -> 1.0825679 | O39: =I39+K39+F39 -> 76.877568 | P39: 76.87 | Q39: =O39-P39 -> 0.0075679359 | T39: =S39-R39 -> 0 | X39: 3 | Z39: =(Y39-O39)+0.25 -> -76.627568
A40: 39 | B40: NT CRUSH | C40: 15 | D40: N | E40: 1 | F40: 59.006 | G40: 3 | H40: 12 | I40: =SUM(G40:H40) -> 15 | J40: 0.34250755 | K40: =(J40*I40)*0.6 -> 3.0825679 | L40: 0 | M40: 0 | N40: =K40-(L40+M40) -> 3.0825679 | O40: =I40+K40+F40 -> 77.088568 | P40: 77.08 | Q40: =O40-P40 -> 0.0085679359 | T40: =S40-R40 -> 0 | X40: 3 | Z40: =(Y40-O40)+0.25 -> -76.838568
...

Sheet 7-24-13 Initial
B1: 区・条件 | C1: STD ppm | F1: year | G1: month | H1: day | I1: hh | J1: mm | K1: ss | L1: sample number | M1: CO2rt | N1: CO2hi | O1: CO2area | P1: 右は計算領域 | Q1: CO2(ppm)初期標準 | R1: ドリフト時計算 | S1: 絶対時間（ｈ） | T1: ドリフトstd factor | U1: CO2(ppm)
C2: CO2 0.9047% | D2: sample前 | F2: 2013 | G2: 7 | H2: 24 | I2: 17 | J2: 13 | O2: 175213 | S2: =H2*24+I2+J2/60+K2/3600 -> 593.21667
B3: CO２ | C3: CO2 0.9047% | D3: sample前 | F3: 2013 | G3: 7 | H3: 24 | I3: 17 | J3: 14 | O3: 177598 | S3: =H3*24+I3+J3/60+K3/3600 -> 593.23333
B4: 9047 | C4: CO2 0.9047% | D4: sample前 | F4: 2013 | G4: 7 | H4: 24 | I4: 17 | J4: 14 | O4: 165664 | S4: =H4*24+I4+J4/60+K4/3600 -> 593.23333
C5: CO2 0.9047% | D5: sample前 | F5: 2013 | G5: 7 | H5: 24 | I5: 17 | J5: 15 | O5: 163066 | S5: =H5*24+I5+J5/60+K5/3600 -> 593.25
C7: CO2 0.9047% | D7: sample後 | F7: 2013 | G7: 7 | H7: 24 | I7: 18 | J7: 49 | O7: 164726 | S7: =H7*24+I7+J7/60+K7/3600 -> 594.81667
C8: CO2 0.9047% | D8: sample後 | F8: 2013 | G8: 7 | H8: 24 | I8: 18 | J8: 50 | O8: 172890 | S8: =H8*24+I8+J8/60+K8/3600 -> 594.83333
C9: CO2 0.9047% | D9: sample後 | F9: 2013 | G9: 7 | H9: 24 | I9: 18 | J9: 51 | O9: 170208 | S9: =H9*24+I9+J9/60+K9/3600 -> 594.85
C10: CO2 0.9047% | D10: sample後
B14: 標準パラメータ | Q14: factor
C15: CO2濃度 | D15: CO2 | F15: 9047 | G15: ppm | H15: 前 | M15: =AVERAGE(M2:M6) -> #DIV/0! | N15: =AVERAGE(N2:N6) -> #DIV/0! | O15: =AVERAGE(O2:O6) -> 170385.25 | Q15: =F15/O15 -> 0.053097319 | S15: =AVERAGE(S2:S6) -> 593.23333
H16: 後 | M16: =AVERAGE(M7:M11) -> #DIV/0! | N16: =AVERAGE(N7:N11) -> #DIV/0! | O16: =AVERAGE(O7:O11) -> 169274.67 | Q16: =F15/O16 -> 0.053445682 | S16: =AVERAGE(S7:S11) -> 594.83333
Q18: 初期std利用 | U18: ドリフト補正有
B19: 15 deg | C19: 1 | F19: 2013 | G19: 7 | H19: 24 | I19: 17 | J19: 17 | O19: 21254 | Q19: =O19*$Q$15 -> 1128.5304 | S19: =H19*24+I19+J19/60+K19/3600 -> 593.28333 | T19: =Q15+(Q16-Q15)*(S19-S15)/(S16-S15) -> 0.053108206 | U19: =O19*T19 -> 1128.7618
C20: 2 | F20: 2013 | G20: 7 | H20: 24 | I20: 17 | J20: 18 | O20: 25712 | Q20: =O20*$Q$15 -> 1365.2383 | S20: =H20*24+I20+J20/60+K20/3600 -> 593.3 | T20: =Q15+(Q16-Q15)*(S20-S15)/(S16-S15) -> 0.053111834 | U20: =O20*T20 -> 1365.6115
C21: 3 | F21: 2013 | G21: 7 | H21: 24 | I21: 17 | J21: 19 | O21: 20458 | Q21: =O21*$Q$15 -> 1086.265 | S21: =H21*24+I21+J21/60+K21/3600 -> 593.31667 | T21: =Q15+(Q16-Q15)*(S21-S15)/(S16-S15) -> 0.053115463 | U21: =O21*T21 -> 1086.6361
C22: 4 | F22: 2013 | G22: 7 | H22: 24 | I22: 17 | J22: 28 | O22: 21651 | Q22: =O22*$Q$15 -> 1149.6101 | S22: =H22*24+I22+J22/60+K22/3600 -> 593.46667 | T22: =Q15+(Q16-Q15)*(S22-S15)/(S16-S15) -> 0.053148122 | U22: =O22*T22 -> 1150.71
C23: 5 | F23: 2013 | G23: 7 | H23: 24 | I23: 17 | J23: 21 | O23: 22893 | Q23: =O23*$Q$15 -> 1215.5569 | S23: =H23*24+I23+J23/60+K23/3600 -> 593.35 | T23: =Q15+(Q16-Q15)*(S23-S15)/(S16-S15) -> 0.053122721 | U23: =O23*T23 -> 1216.1384
C24: 6 | F24: 2013 | G24: 7 | H24: 24 | I24: 17 | J24: 21 | O24: 16330 | Q24: =O24*$Q$15 -> 867.07922 | S24: =H24*24+I24+J24/60+K24/3600 -> 593.35 | T24: =Q15+(Q16-Q15)*(S24-S15)/(S16-S15) -> 0.053122721 | U24: =O24*T24 -> 867.49403
C25: 7 | F25: 2013 | G25: 7 | H25: 24 | I25: 17 | J25: 22 | O25: 17274 | Q25: =O25*$Q$15 -> 917.20309 | S25: =H25*24+I25+J25/60+K25/3600 -> 593.36667 | T25: =Q15+(Q16-Q15)*(S25-S15)/(S16-S15) -> 0.053126349 | U25: =O25*T25 -> 917.70456
C26: 8 | F26: 2013 | G26: 7 | H26: 24 | I26: 17 | J26: 23 | O26: 16160 | Q26: =O26*$Q$15 -> 858.05268 | S26: =H26*24+I26+J26/60+K26/3600 -> 593.38333 | T26: =Q15+(Q16-Q15)*(S26-S15)/(S16-S15) -> 0.053129978 | U26: =O26*T26 -> 858.58045
C27: 9 | F27: 2013 | G27: 7 | H27: 24 | I27: 17 | J27: 24 | O27: 16195 | Q27: =O27*$Q$15 -> 859.91108 | S27: =H27*24+I27+J27/60+K27/3600 -> 593.4 | T27: =Q15+(Q16-Q15)*(S27-S15)/(S16-S15) -> 0.053133607 | U27: =O27*T27 -> 860.49876
C28: 10 | F28: 2013 | G28: 7 | H28: 24 | I28: 17 | J28: 25 | O28: 18688 | Q28: =O28*$Q$15 -> 992.2827 | S28: =H28*24+I28+J28/60+K28/3600 -> 593.41667 | T28: =Q15+(Q16-Q15)*(S28-S15)/(S16-S15) -> 0.053137236 | U28: =O28*T28 -> 993.02866
C29: 12 | F29: 2013 | G29: 7 | H29: 24 | I29: 17 | J29: 26 | O29: 18197 | Q29: =O29*$Q$15 -> 966.21192 | S29: =H29*24+I29+J29/60+K29/3600 -> 593.43333 | T29: =Q15+(Q16-Q15)*(S29-S15)/(S16-S15) -> 0.053140865 | U29: =O29*T29 -> 967.00431
C30: 13 | F30: 2013 | G30: 7 | H30: 24 | I30: 17 | J30: 27 | O30: 15749 | Q30: =O30*$Q$15 -> 836.22968 | S30: =H30*24+I30+J30/60+K30/3600 -> 593.45 | T30: =Q15+(Q16-Q15)*(S30-S15)/(S16-S15) -> 0.053144493 | U30: =O30*T30 -> 836.97262
C31: 14 | F31: 2013 | G31: 7 | H31: 24 | I31: 17 | J31: 30 | O31: 16325 | Q31: =O31*$Q$15 -> 866.81374 | S31: =H31*24+I31+J31/60+K31/3600 -> 593.5 | T31: =Q15+(Q16-Q15)*(S31-S15)/(S16-S15) -> 0.05315538 | U31: =O31*T31 -> 867.76157
C32: 85 | F32: 2013 | G32: 7 | H32: 24 | I32: 17 | J32: 29 | O32: 11125 | Q32: =O32*$Q$15 -> 590.70768 | S32: =H32*24+I32+J32/60+K32/3600 -> 593.48333 | T32: =Q15+(Q16-Q15)*(S32-S15)/(S16-S15) -> 0.053151751 | U32: =O32*T32 -> 591.31323
C33: 15 | F33: 2013 | G33: 7 | H33: 24 | I33: 17 | J33: 31 | O33: 30637 | Q33: =O33*$Q$15 -> 1626.7426 | S33: =H33*24+I33+J33/60+K33/3600 -> 593.51667 | T33: =Q15+(Q16-Q15)*(S33-S15)/(S16-S15) -> 0.053159008 | U33: =O33*T33 -> 1628.6325
C34: 16 | F34: 2013 | G34: 7 | H34: 24 | I34: 17 | J34: 32 | O34: 30864 | Q34: =O34*$Q$15 -> 1638.7957 | S34: =H34*24+I34+J34/60+K34/3600 -> 593.53333 | T34: =Q15+(Q16-Q15)*(S34-S15)/(S16-S15) -> 0.053162637 | U34: =O34*T34 -> 1640.8116
C35: 17 | F35: 2013 | G35: 7 | H35: 24 | I35: 17 | J35: 33 | O35: 28986 | Q35: =O35*$Q$15 -> 1539.0789 | S35: =H35*24+I35+J35/60+K35/3600 -> 593.55 | T35: =Q15+(Q16-Q15)*(S35-S15)/(S16-S15) -> 0.053166266 | U35: =O35*T35 -> 1541.0774
C36: 18 | F36: 2013 | G36: 7 | H36: 24 | I36: 17 | J36: 34 | O36: 33704 | Q36: =O36*$Q$15 -> 1789.592 | S36: =H36*24+I36+J36/60+K36/3600 -> 593.56667 | T36: =Q15+(Q16-Q15)*(S36-S15)/(S16-S15) -> 0.053169895 | U36: =O36*T36 -> 1792.0381
C37: 19 | F37: 2013 | G37: 7 | H37: 24 | I37: 17 | J37: 35 | O37: 32722 | Q37: =O37*$Q$15 -> 1737.4505 | S37: =H37*24+I37+J37/60+K37/3600 -> 593.58333 | T37: =Q15+(Q16-Q15)*(S37-S15)/(S16-S15) -> 0.053173524 | U37: =O37*T37 -> 1739.944
C38: 20 | F38: 2013 | G38: 7 | H38: 24 | I38: 17 | J38: 37 | O38: 26467 | Q38: =O38*$Q$15 -> 1405.3267 | S38: =H38*24+I38+J38/60+K38/3600 -> 593.61667 | T38: =Q15+(Q16-Q15)*(S38-S15)/(S16-S15) -> 0.053180781 | U38: =O38*T38 -> 1407.5357
C39: 21 | F39: 2013 | G39: 7 | H39: 24 | I39: 17 | J39: 38 | O39: 24160 | Q39: =O39*$Q$15 -> 1282.8312 | S39: =H39*24+I39+J39/60+K39/3600 -> 593.63333 | T39: =Q15+(Q16-Q15)*(S39-S15)/(S16-S15) -> 0.05318441 | U39: =O39*T39 -> 1284.9353
C40: 22 | F40: 2013 | G40: 7 | H40: 24 | I40: 17 | J40: 39 | O40: 23147 | Q40: =O40*$Q$15 -> 1229.0436 | S40: =H40*24+I40+J40/60+K40/3600 -> 593.65 | T40: =Q15+(Q16-Q15)*(S40-S15)/(S16-S15) -> 0.053188039 | U40: =O40*T40 -> 1231.1435
C41: 23 | F41: 2013 | G41: 7 | H41: 24 | I41: 17 | J41: 40 | O41: 24509 | Q41: =O41*$Q$15 -> 1301.3622 | S41: =H41*24+I41+J41/60+K41/3600 -> 593.66667 | T41: =Q15+(Q16-Q15)*(S41-S15)/(S16-S15) -> 0.053191667 | U41: =O41*T41 -> 1303.6746
C42: 24 | F42: 2013 | G42: 7 | H42: 24 | I42: 17 | J42: 41 | O42: 24368 | Q42: =O42*$Q$15 -> 1293.8755 | S42: =H42*24+I42+J42/60+K42/3600 -> 593.68333 | T42: =Q15+(Q16-Q15)*(S42-S15)/(S16-S15) -> 0.053195296 | U42: =O42*T42 -> 1296.263
C43: 25 | F43: 2013 | G43: 7 | H43: 24 | I43: 17 | J43: 43 | O43: 30237 | Q43: =O43*$Q$15 -> 1605.5036 | S43: =H43*24+I43+J43/60+K43/3600 -> 593.71667 | T43: =Q15+(Q16-Q15)*(S43-S15)/(S16-S15) -> 0.053202554 | U43: =O43*T43 -> 1608.6856
C44: 26 | F44: 2013 | G44: 7 | H44: 24 | I44: 17 | J44: 42 | O44: 25862 | Q44: =O44*$Q$15 -> 1373.2029 | S44: =H44*24+I44+J44/60+K44/3600 -> 593.7 | T44: =Q15+(Q16-Q15)*(S44-S15)/(S16-S15) -> 0.053198925 | U44: =O44*T44 -> 1375.8306
C45: 27 | F45: 2013 | G45: 7 | H45: 24 | I45: 17 | J45: 44 | O45: 31542 | Q45: =O45*$Q$15 -> 1674.7956 | S45: =H45*24+I45+J45/60+K45/3600 -> 593.73333 | T45: =Q15+(Q16-Q15)*(S45-S15)/(S16-S15) -> 0.053206183 | U45: =O45*T45 -> 1678.2294
...

Sheet 7-24-13 Final
B1: 区・条件 | C1: STD ppm | F1: year | G1: month | H1: day | I1: hh | J1: mm | K1: ss | L1: sample number | M1: CO2rt | N1: CO2hi | O1: CO2area | P1: 右は計算領域 | Q1: CO2(ppm)初期標準 | R1: ドリフト時計算 | S1: 絶対時間（ｈ） | T1: ドリフトstd factor | U1: CO2(ppm)
C2: CO2 0.9047% | D2: sample前 | F2: 2013 | G2: 7 | H2: 24 | I2: 18 | J2: 49 | O2: 164726 | S2: =H2*24+I2+J2/60+K2/3600 -> 594.81667
B3: CO２ | C3: CO2 0.9047% | D3: sample前 | F3: 2013 | G3: 7 | H3: 24 | I3: 18 | J3: 50 | O3: 172890 | S3: =H3*24+I3+J3/60+K3/3600 -> 594.83333
B4: 9047 | C4: CO2 0.9047% | D4: sample前 | F4: 2013 | G4: 7 | H4: 24 | I4: 18 | J4: 51 | O4: 170208 | S4: =H4*24+I4+J4/60+K4/3600 -> 594.85
C5: CO2 0.9047% | D5: sample前
C7: CO2 0.9047% | D7: sample後 | F7: 2013 | G7: 7 | H7: 24 | I7: 20 | J7: 59 | O7: 149056 | S7: =H7*24+I7+J7/60+K7/3600 -> 596.98333
C8: CO2 0.9047% | D8: sample後 | F8: 2013 | G8: 7 | H8: 24 | I8: 21 | J8: 0 | O8: 156659 | S8: =H8*24+I8+J8/60+K8/3600 -> 597
C9: CO2 0.9047% | D9: sample後 | F9: 2013 | G9: 7 | H9: 24 | I9: 21 | J9: 1 | O9: 155427 | S9: =H9*24+I9+J9/60+K9/3600 -> 597.01667
C10: CO2 0.9047% | D10: sample後 | F10: 2013 | G10: 7 | H10: 24 | I10: 21 | J10: 2 | O10: 158546 | S10: =H10*24+I10+J10/60+K10/3600 -> 597.03333
C11: CO2 0.9047% | D11: sample後 | F11: 2013 | G11: 7 | H11: 24 | I11: 21 | J11: 3 | O11: 155869 | S11: =H11*24+I11+J11/60+K11/3600 -> 597.05
B14: 標準パラメータ | Q14: factor
C15: CO2濃度 | D15: CO2 | F15: 9047 | G15: ppm | H15: 前 | M15: =AVERAGE(M2:M6) -> #DIV/0! | N15: =AVERAGE(N2:N6) -> #DIV/0! | O15: =AVERAGE(O2:O6) -> 169274.67 | Q15: =F15/O15 -> 0.053445682 | S15: =AVERAGE(S2:S6) -> 594.83333
H16: 後 | M16: =AVERAGE(M7:M11) -> #DIV/0! | N16: =AVERAGE(N7:N11) -> #DIV/0! | O16: =AVERAGE(O7:O11) -> 155111.4 | Q16: =F15/O16 -> 0.058325823 | S16: =AVERAGE(S7:S11) -> 597.01667
Q18: 初期std利用 | U18: ドリフト補正有
B19: 15 deg | C19: 1 | F19: 2013 | G19: 7 | H19: 24 | I19: 19 | J19: 3 | O19: 22614 | Q19: =O19*$Q$15 -> 1208.6207 | S19: =H19*24+I19+J19/60+K19/3600 -> 595.05 | T19: =Q15+(Q16-Q15)*(S19-S15)/(S16-S15) -> 0.053929971 | U19: =O19*T19 -> 1219.5724
C20: 2 | F20: 2013 | G20: 7 | H20: 24 | I20: 19 | J20: 4 | O20: 27542 | Q20: =O20*$Q$15 -> 1472.001 | S20: =H20*24+I20+J20/60+K20/3600 -> 595.06667 | T20: =Q15+(Q16-Q15)*(S20-S15)/(S16-S15) -> 0.053967224 | U20: =O20*T20 -> 1486.3653
C21: 3 | F21: 2013 | G21: 7 | H21: 24 | I21: 19 | J21: 5 | O21: 23658 | Q21: =O21*$Q$15 -> 1264.4179 | S21: =H21*24+I21+J21/60+K21/3600 -> 595.08333 | T21: =Q15+(Q16-Q15)*(S21-S15)/(S16-S15) -> 0.054004477 | U21: =O21*T21 -> 1277.6379
C22: 4 | F22: 2013 | G22: 7 | H22: 24 | I22: 19 | J22: 6 | O22: 24125 | Q22: =O22*$Q$15 -> 1289.3771 | S22: =H22*24+I22+J22/60+K22/3600 -> 595.1 | T22: =Q15+(Q16-Q15)*(S22-S15)/(S16-S15) -> 0.05404173 | U22: =O22*T22 -> 1303.7567
C23: 5 | F23: 2013 | G23: 7 | H23: 24 | I23: 19 | J23: 17 | O23: 25811 | Q23: =O23*$Q$15 -> 1379.4865 | S23: =H23*24+I23+J23/60+K23/3600 -> 595.28333 | T23: =Q15+(Q16-Q15)*(S23-S15)/(S16-S15) -> 0.054451512 | U23: =O23*T23 -> 1405.448
C24: 6 | F24: 2013 | G24: 7 | H24: 24 | I24: 19 | J24: 18 | O24: 18448 | Q24: =O24*$Q$15 -> 985.96594 | S24: =H24*24+I24+J24/60+K24/3600 -> 595.3 | T24: =Q15+(Q16-Q15)*(S24-S15)/(S16-S15) -> 0.054488765 | U24: =O24*T24 -> 1005.2087
C25: 7 | F25: 2013 | G25: 7 | H25: 24 | I25: 19 | J25: 19 | O25: 18376 | Q25: =O25*$Q$15 -> 982.11785 | S25: =H25*24+I25+J25/60+K25/3600 -> 595.31667 | T25: =Q15+(Q16-Q15)*(S25-S15)/(S16-S15) -> 0.054526018 | U25: =O25*T25 -> 1001.9701
C26: 8 | F26: 2013 | G26: 7 | H26: 24 | I26: 19 | J26: 19 | O26: 18243 | Q26: =O26*$Q$15 -> 975.00958 | S26: =H26*24+I26+J26/60+K26/3600 -> 595.31667 | T26: =Q15+(Q16-Q15)*(S26-S15)/(S16-S15) -> 0.054526018 | U26: =O26*T26 -> 994.71815
C27: 9 | F27: 2013 | G27: 7 | H27: 24 | I27: 19 | J27: 20 | O27: 18931 | Q27: =O27*$Q$15 -> 1011.7802 | S27: =H27*24+I27+J27/60+K27/3600 -> 595.33333 | T27: =Q15+(Q16-Q15)*(S27-S15)/(S16-S15) -> 0.054563271 | U27: =O27*T27 -> 1032.9373
C28: 10 | F28: 2013 | G28: 7 | H28: 24 | I28: 19 | J28: 21 | O28: 20451 | Q28: =O28*$Q$15 -> 1093.0176 | S28: =H28*24+I28+J28/60+K28/3600 -> 595.35 | T28: =Q15+(Q16-Q15)*(S28-S15)/(S16-S15) -> 0.054600524 | U28: =O28*T28 -> 1116.6353
C29: 12 | F29: 2013 | G29: 7 | H29: 24 | I29: 19 | J29: 22 | O29: 18672 | Q29: =O29*$Q$15 -> 997.93777 | S29: =H29*24+I29+J29/60+K29/3600 -> 595.36667 | T29: =Q15+(Q16-Q15)*(S29-S15)/(S16-S15) -> 0.054637777 | U29: =O29*T29 -> 1020.1966
C30: 13 | F30: 2013 | G30: 7 | H30: 24 | I30: 19 | J30: 48 | O30: 17696 | Q30: =O30*$Q$15 -> 945.77479 | S30: =H30*24+I30+J30/60+K30/3600 -> 595.8 | T30: =Q15+(Q16-Q15)*(S30-S15)/(S16-S15) -> 0.055606355 | U30: =O30*T30 -> 984.01006
C31: 14 | F31: 2013 | G31: 7 | H31: 24 | I31: 19 | J31: 49 | O31: 18762 | Q31: =O31*$Q$15 -> 1002.7479 | S31: =H31*24+I31+J31/60+K31/3600 -> 595.81667 | T31: =Q15+(Q16-Q15)*(S31-S15)/(S16-S15) -> 0.055643608 | U31: =O31*T31 -> 1043.9854
C32: 85 | F32: 2013 | G32: 7 | H32: 24 | I32: 19 | J32: 50 | O32: 10848 | Q32: =O32*$Q$15 -> 579.77876 | S32: =H32*24+I32+J32/60+K32/3600 -> 595.83333 | T32: =Q15+(Q16-Q15)*(S32-S15)/(S16-S15) -> 0.055680861 | U32: =O32*T32 -> 604.02598
C33: 15 | F33: 2013 | G33: 7 | H33: 24 | I33: 19 | J33: 7 | O33: 30982 | Q33: =O33*$Q$15 -> 1655.8541 | S33: =H33*24+I33+J33/60+K33/3600 -> 595.11667 | T33: =Q15+(Q16-Q15)*(S33-S15)/(S16-S15) -> 0.054078983 | U33: =O33*T33 -> 1675.475
C34: 16 | F34: 2013 | G34: 7 | H34: 24 | I34: 19 | J34: 8 | O34: 32019 | Q34: =O34*$Q$15 -> 1711.2773 | S34: =H34*24+I34+J34/60+K34/3600 -> 595.13333 | T34: =Q15+(Q16-Q15)*(S34-S15)/(S16-S15) -> 0.054116236 | U34: =O34*T34 -> 1732.7477
C35: 17 | F35: 2013 | G35: 7 | H35: 24 | I35: 19 | J35: 52 | O35: 48704 | Q35: =O35*$Q$15 -> 2603.0185 | S35: =H35*24+I35+J35/60+K35/3600 -> 595.86667 | T35: =Q15+(Q16-Q15)*(S35-S15)/(S16-S15) -> 0.055755367 | U35: =O35*T35 -> 2715.5094
C36: 18 | F36: 2013 | G36: 7 | H36: 24 | I36: 19 | J36: 53 | O36: 38168 | Q36: =O36*$Q$15 -> 2039.9148 | S36: =H36*24+I36+J36/60+K36/3600 -> 595.88333 | T36: =Q15+(Q16-Q15)*(S36-S15)/(S16-S15) -> 0.05579262 | U36: =O36*T36 -> 2129.4927
C37: 19 | F37: 2013 | G37: 7 | H37: 24 | I37: 19 | J37: 54 | O37: 39910 | Q37: =O37*$Q$15 -> 2133.0172 | S37: =H37*24+I37+J37/60+K37/3600 -> 595.9 | T37: =Q15+(Q16-Q15)*(S37-S15)/(S16-S15) -> 0.055829873 | U37: =O37*T37 -> 2228.1702
C38: 20 | F38: 2013 | G38: 7 | H38: 24 | I38: 19 | J38: 55 | O38: 30955 | Q38: =O38*$Q$15 -> 1654.4111 | S38: =H38*24+I38+J38/60+K38/3600 -> 595.91667 | T38: =Q15+(Q16-Q15)*(S38-S15)/(S16-S15) -> 0.055867126 | U38: =O38*T38 -> 1729.3669
C39: 21 | F39: 2013 | G39: 7 | H39: 24 | I39: 20 | J39: 0 | O39: 28189 | Q39: =O39*$Q$15 -> 1506.5803 | S39: =H39*24+I39+J39/60+K39/3600 -> 596 | T39: =Q15+(Q16-Q15)*(S39-S15)/(S16-S15) -> 0.056053391 | U39: =O39*T39 -> 1580.089
C40: 22 | F40: 2013 | G40: 7 | H40: 24 | I40: 20 | J40: 1 | O40: 26968 | Q40: =O40*$Q$15 -> 1441.3232 | S40: =H40*24+I40+J40/60+K40/3600 -> 596.01667 | T40: =Q15+(Q16-Q15)*(S40-S15)/(S16-S15) -> 0.056090644 | U40: =O40*T40 -> 1512.6525
C41: 23 | F41: 2013 | G41: 7 | H41: 24 | I41: 20 | J41: 2 | O41: 28278 | Q41: =O41*$Q$15 -> 1511.337 | S41: =H41*24+I41+J41/60+K41/3600 -> 596.03333 | T41: =Q15+(Q16-Q15)*(S41-S15)/(S16-S15) -> 0.056127897 | U41: =O41*T41 -> 1587.1847
C42: 24 | F42: 2013 | G42: 7 | H42: 24 | I42: 20 | J42: 3 | O42: 27891 | Q42: =O42*$Q$15 -> 1490.6535 | S42: =H42*24+I42+J42/60+K42/3600 -> 596.05 | T42: =Q15+(Q16-Q15)*(S42-S15)/(S16-S15) -> 0.05616515 | U42: =O42*T42 -> 1566.5022
C43: 25 | F43: 2013 | G43: 7 | H43: 24 | I43: 20 | J43: 4 | O43: 36099 | Q43: =O43*$Q$15 -> 1929.3357 | S43: =H43*24+I43+J43/60+K43/3600 -> 596.06667 | T43: =Q15+(Q16-Q15)*(S43-S15)/(S16-S15) -> 0.056202403 | U43: =O43*T43 -> 2028.8505
C44: 26 | F44: 2013 | G44: 7 | H44: 24 | I44: 20 | J44: 4 | O44: 32160 | Q44: =O44*$Q$15 -> 1718.8131 | S44: =H44*24+I44+J44/60+K44/3600 -> 596.06667 | T44: =Q15+(Q16-Q15)*(S44-S15)/(S16-S15) -> 0.056202403 | U44: =O44*T44 -> 1807.4693
...

Sheet 7-29-13 Final #2
B1: 区・条件 | C1: STD ppm | F1: year | G1: month | H1: day | I1: hh | J1: mm | K1: ss | L1: sample number | M1: CO2rt | N1: CO2hi | O1: CO2area | P1: 右は計算領域 | Q1: CO2(ppm)初期標準 | R1: ドリフト時計算 | S1: 絶対時間（ｈ） | T1: ドリフトstd factor | U1: CO2(ppm)
C2: CO2 0.9047% | D2: sample前 | F2: 2013 | G2: 7 | H2: 29 | I2: 11 | J2: 27 | O2: 174986 | S2: =H2*24+I2+J2/60+K2/3600 -> 707.45
B3: CO２ | C3: CO2 0.9047% | D3: sample前 | F3: 2013 | G3: 7 | H3: 29 | I3: 11 | J3: 28 | O3: 177562 | S3: =H3*24+I3+J3/60+K3/3600 -> 707.46667
B4: 9047 | C4: CO2 0.9047% | D4: sample前 | F4: 2013 | G4: 7 | H4: 29 | I4: 11 | J4: 28 | O4: 174275 | S4: =H4*24+I4+J4/60+K4/3600 -> 707.46667
C5: CO2 0.9047% | D5: sample前 | F5: 2013 | G5: 7 | H5: 29 | I5: 11 | J5: 29 | O5: 176619 | S5: =H5*24+I5+J5/60+K5/3600 -> 707.48333
C7: CO2 0.9047% | D7: sample後 | F7: 2013 | G7: 7 | H7: 29 | I7: 14 | J7: 10 | O7: 170243 | S7: =H7*24+I7+J7/60+K7/3600 -> 710.16667
C8: CO2 0.9047% | D8: sample後 | F8: 2013 | G8: 7 | H8: 29 | I8: 14 | J8: 11 | O8: 168307 | S8: =H8*24+I8+J8/60+K8/3600 -> 710.18333
C9: CO2 0.9047% | D9: sample後 | F9: 2013 | G9: 7 | H9: 29 | I9: 14 | J9: 12 | O9: 173875 | S9: =H9*24+I9+J9/60+K9/3600 -> 710.2
C10: CO2 0.9047% | D10: sample後 | F10: 2013 | G10: 7 | H10: 29 | I10: 14 | J10: 12 | O10: 175776 | S10: =H10*24+I10+J10/60+K10/3600 -> 710.2
B14: 標準パラメータ | Q14: factor
C15: CO2濃度 | D15: CO2 | F15: 9047 | G15: ppm | H15: 前 | M15: =AVERAGE(M2:M6) -> #DIV/0! | N15: =AVERAGE(N2:N6) -> #DIV/0! | O15: =AVERAGE(O2:O6) -> 175860.5 | Q15: =F15/O15 -> 0.051444184 | S15: =AVERAGE(S2:S6) -> 707.46667
H16: 後 | M16: =AVERAGE(M7:M11) -> #DIV/0! | N16: =AVERAGE(N7:N11) -> #DIV/0! | O16: =AVERAGE(O7:O11) -> 172050.25 | Q16: =F15/O16 -> 0.052583475 | S16: =AVERAGE(S7:S11) -> 710.1875
Q18: 初期std利用 | U18: ドリフト補正有
B19: 15 deg | C19: 1 | F19: 2013 | G19: 7 | H19: 29 | I19: 13 | J19: 21 | O19: 176258 | Q19: =O19*$Q$15 -> 9067.4491 | S19: =H19*24+I19+J19/60+K19/3600 -> 709.35 | T19: =Q15+(Q16-Q15)*(S19-S15)/(S16-S15) -> 0.05223279 | U19: =O19*T19 -> 9206.4471
C20: 2 | F20: 2013 | G20: 7 | H20: 29 | I20: 13 | J20: 22 | O20: 178963 | Q20: =O20*$Q$15 -> 9206.6056 | S20: =H20*24+I20+J20/60+K20/3600 -> 709.36667 | T20: =Q15+(Q16-Q15)*(S20-S15)/(S16-S15) -> 0.052239769 | U20: =O20*T20 -> 9348.9857
C21: 3 | F21: 2013 | G21: 7 | H21: 29 | I21: 13 | J21: 23 | O21: 152534 | Q21: =O21*$Q$15 -> 7846.9872 | S21: =H21*24+I21+J21/60+K21/3600 -> 709.38333 | T21: =Q15+(Q16-Q15)*(S21-S15)/(S16-S15) -> 0.052246747 | U21: =O21*T21 -> 7969.4054
C22: 4 | F22: 2013 | G22: 7 | H22: 29 | I22: 13 | J22: 24 | O22: 162445 | Q22: =O22*$Q$15 -> 8356.8505 | S22: =H22*24+I22+J22/60+K22/3600 -> 709.4 | T22: =Q15+(Q16-Q15)*(S22-S15)/(S16-S15) -> 0.052253726 | U22: =O22*T22 -> 8488.3566
C23: 5 | F23: 2013 | G23: 7 | H23: 29 | I23: 13 | J23: 25 | O23: 177594 | Q23: =O23*$Q$15 -> 9136.1785 | S23: =H23*24+I23+J23/60+K23/3600 -> 709.41667 | T23: =Q15+(Q16-Q15)*(S23-S15)/(S16-S15) -> 0.052260705 | U23: =O23*T23 -> 9281.1876
C24: 6 | F24: 2013 | G24: 7 | H24: 29 | I24: 13 | J24: 26 | O24: 105960 | Q24: =O24*$Q$15 -> 5451.0258 | S24: =H24*24+I24+J24/60+K24/3600 -> 709.43333 | T24: =Q15+(Q16-Q15)*(S24-S15)/(S16-S15) -> 0.052267684 | U24: =O24*T24 -> 5538.2838
C25: 7 | F25: 2013 | G25: 7 | H25: 29 | I25: 13 | J25: 27 | O25: 125338 | Q25: =O25*$Q$15 -> 6447.9112 | S25: =H25*24+I25+J25/60+K25/3600 -> 709.45 | T25: =Q15+(Q16-Q15)*(S25-S15)/(S16-S15) -> 0.052274663 | U25: =O25*T25 -> 6552.0017
C26: 8 | F26: 2013 | G26: 7 | H26: 29 | I26: 13 | J26: 28 | O26: 119882 | Q26: =O26*$Q$15 -> 6167.2317 | S26: =H26*24+I26+J26/60+K26/3600 -> 709.46667 | T26: =Q15+(Q16-Q15)*(S26-S15)/(S16-S15) -> 0.052281641 | U26: =O26*T26 -> 6267.6277
C27: 9 | F27: 2013 | G27: 7 | H27: 29 | I27: 13 | J27: 29 | O27: 139987 | Q27: =O27*$Q$15 -> 7201.517 | S27: =H27*24+I27+J27/60+K27/3600 -> 709.48333 | T27: =Q15+(Q16-Q15)*(S27-S15)/(S16-S15) -> 0.05228862 | U27: =O27*T27 -> 7319.7271
C28: 10 | F28: 2013 | G28: 7 | H28: 29 | I28: 13 | J28: 30 | O28: 151595 | Q28: =O28*$Q$15 -> 7798.6811 | S28: =H28*24+I28+J28/60+K28/3600 -> 709.5 | T28: =Q15+(Q16-Q15)*(S28-S15)/(S16-S15) -> 0.052295599 | U28: =O28*T28 -> 7927.7513
C29: 12 | F29: 2013 | G29: 7 | H29: 29 | I29: 13 | J29: 35 | O29: 59602 | Q29: =O29*$Q$15 -> 3066.1763 | S29: =H29*24+I29+J29/60+K29/3600 -> 709.58333 | T29: =Q15+(Q16-Q15)*(S29-S15)/(S16-S15) -> 0.052330493 | U29: =O29*T29 -> 3119.002
C30: 13 | F30: 2013 | G30: 7 | H30: 29 | I30: 13 | J30: 34 | O30: 46666 | Q30: =O30*$Q$15 -> 2400.6943 | S30: =H30*24+I30+J30/60+K30/3600 -> 709.56667 | T30: =Q15+(Q16-Q15)*(S30-S15)/(S16-S15) -> 0.052323514 | U30: =O30*T30 -> 2441.7291
C31: 14 | F31: 2013 | G31: 7 | H31: 29 | I31: 13 | J31: 37 | O31: 52077 | Q31: =O31*$Q$15 -> 2679.0588 | S31: =H31*24+I31+J31/60+K31/3600 -> 709.61667 | T31: =Q15+(Q16-Q15)*(S31-S15)/(S16-S15) -> 0.052344451 | U31: =O31*T31 -> 2725.942
C32: 85 | F32: 2013 | G32: 7 | H32: 29 | I32: 13 | J32: 38 | O32: 11176 | Q32: =O32*$Q$15 -> 574.94021 | S32: =H32*24+I32+J32/60+K32/3600 -> 709.63333 | T32: =Q15+(Q16-Q15)*(S32-S15)/(S16-S15) -> 0.05235143 | U32: =O32*T32 -> 585.07958
C33: 15 | F33: 2013 | G33: 7 | H33: 29 | I33: 13 | J33: 40 | O33: 392928 | Q33: =O33*$Q$15 -> 20213.861 | S33: =H33*24+I33+J33/60+K33/3600 -> 709.66667 | T33: =Q15+(Q16-Q15)*(S33-S15)/(S16-S15) -> 0.052365387 | U33: =O33*T33 -> 20575.827
C34: 16 | F34: 2013 | G34: 7 | H34: 29 | I34: 13 | J34: 41 | O34: 367312 | Q34: =O34*$Q$15 -> 18896.066 | S34: =H34*24+I34+J34/60+K34/3600 -> 709.68333 | T34: =Q15+(Q16-Q15)*(S34-S15)/(S16-S15) -> 0.052372366 | U34: =O34*T34 -> 19236.998
C35: 17 | F35: 2013 | G35: 7 | H35: 29 | I35: 13 | J35: 42 | O35: 365349 | Q35: =O35*$Q$15 -> 18795.081 | S35: =H35*24+I35+J35/60+K35/3600 -> 709.7 | T35: =Q15+(Q16-Q15)*(S35-S15)/(S16-S15) -> 0.052379345 | U35: =O35*T35 -> 19136.741
C36: 18 | F36: 2013 | G36: 7 | H36: 29 | I36: 13 | J36: 43 | O36: 427415 | Q36: =O36*$Q$15 -> 21988.016 | S36: =H36*24+I36+J36/60+K36/3600 -> 709.71667 | T36: =Q15+(Q16-Q15)*(S36-S15)/(S16-S15) -> 0.052386324 | U36: =O36*T36 -> 22390.7
C37: 19 | F37: 2013 | G37: 7 | H37: 29 | I37: 13 | J37: 44 | O37: 416714 | Q37: =O37*$Q$15 -> 21437.512 | S37: =H37*24+I37+J37/60+K37/3600 -> 709.73333 | T37: =Q15+(Q16-Q15)*(S37-S15)/(S16-S15) -> 0.052393302 | U37: =O37*T37 -> 21833.023
C38: 20 | F38: 2013 | G38: 7 | H38: 29 | I38: 13 | J38: 45 | O38: 143011 | Q38: =O38*$Q$15 -> 7357.0843 | S38: =H38*24+I38+J38/60+K38/3600 -> 709.75 | T38: =Q15+(Q16-Q15)*(S38-S15)/(S16-S15) -> 0.052400281 | U38: =O38*T38 -> 7493.8166
C39: 21 | F39: 2013 | G39: 7 | H39: 29 | I39: 13 | J39: 46 | O39: 135389 | Q39: =O39*$Q$15 -> 6964.9767 | S39: =H39*24+I39+J39/60+K39/3600 -> 709.76667 | T39: =Q15+(Q16-Q15)*(S39-S15)/(S16-S15) -> 0.05240726 | U39: =O39*T39 -> 7095.3665
C40: 22 | F40: 2013 | G40: 7 | H40: 29 | I40: 13 | J40: 47 | O40: 120394 | Q40: =O40*$Q$15 -> 6193.5711 | S40: =H40*24+I40+J40/60+K40/3600 -> 709.78333 | T40: =Q15+(Q16-Q15)*(S40-S15)/(S16-S15) -> 0.052414239 | U40: =O40*T40 -> 6310.3599
C41: 23 | F41: 2013 | G41: 7 | H41: 29 | I41: 13 | J41: 50 | O41: 120058 | Q41: =O41*$Q$15 -> 6176.2859 | S41: =H41*24+I41+J41/60+K41/3600 -> 709.83333 | T41: =Q15+(Q16-Q15)*(S41-S15)/(S16-S15) -> 0.052435175 | U41: =O41*T41 -> 6295.2623
C42: 24 | F42: 2013 | G42: 7 | H42: 29 | I42: 13 | J42: 49 | O42: 130358 | Q42: =O42*$Q$15 -> 6706.161 | S42: =H42*24+I42+J42/60+K42/3600 -> 709.81667 | T42: =Q15+(Q16-Q15)*(S42-S15)/(S16-S15) -> 0.052428196 | U42: =O42*T42 -> 6834.4348
C43: 25 | F43: 2013 | G43: 7 | H43: 29 | I43: 13 | J43: 51 | O43: 189882 | Q43: =O43*$Q$15 -> 9768.3246 | S43: =H43*24+I43+J43/60+K43/3600 -> 709.85 | T43: =Q15+(Q16-Q15)*(S43-S15)/(S16-S15) -> 0.052442154 | U43: =O43*T43 -> 9957.8211
C44: 26 | F44: 2013 | G44: 7 | H44: 29 | I44: 13 | J44: 52 | O44: 170608 | Q44: =O44*$Q$15 -> 8776.7894 | S44: =H44*24+I44+J44/60+K44/3600 -> 709.86667 | T44: =Q15+(Q16-Q15)*(S44-S15)/(S16-S15) -> 0.052449133 | U44: =O44*T44 -> 8948.2417
C45: 27 | F45: 2013 | G45: 7 | H45: 29 | I45: 13 | J45: 53 | O45: 190046 | Q45: =O45*$Q$15 -> 9776.7615 | S45: =H45*24+I45+J45/60+K45/3600 -> 709.88333 | T45: =Q15+(Q16-Q15)*(S45-S15)/(S16-S15) -> 0.052456112 | U45: =O45*T45 -> 9969.0742
...

Sheet 7-30-13 Initial + cap
B1: 区・条件 | C1: STD ppm | F1: year | G1: month | H1: day | I1: hh | J1: mm | K1: ss | L1: sample number | M1: CO2rt | N1: CO2hi | O1: CO2area | P1: 右は計算領域 | Q1: CO2(ppm)初期標準 | R1: ドリフト時計算 | S1: 絶対時間（ｈ） | T1: ドリフトstd factor | U1: CO2(ppm)
C2: CO2 0.9047% | D2: sample前 | F2: 2013 | G2: 7 | H2: 30 | I2: 13 | J2: 5 | O2: 167766 | S2: =H2*24+I2+J2/60+K2/3600 -> 733.08333
B3: CO２ | C3: CO2 0.9047% | D3: sample前 | F3: 2013 | G3: 7 | H3: 30 | I3: 13 | J3: 6 | O3: 172286 | S3: =H3*24+I3+J3/60+K3/3600 -> 733.1
B4: 9047 | C4: CO2 0.9047% | D4: sample前 | F4: 2013 | G4: 7 | H4: 30 | I4: 13 | J4: 7 | O4: 168659 | S4: =H4*24+I4+J4/60+K4/3600 -> 733.11667
C5: CO2 0.9047% | D5: sample前 | F5: 2013 | G5: 7 | H5: 30 | I5: 13 | J5: 8 | O5: 166397 | S5: =H5*24+I5+J5/60+K5/3600 -> 733.13333
F6: 2013 | G6: 7 | H6: 30 | I6: 13 | J6: 8 | O6: 166445 | S6: =H6*24+I6+J6/60+K6/3600 -> 733.13333
C7: CO2 0.9047% | D7: sample後 | F7: 2013 | G7: 7 | H7: 30 | I7: 15 | J7: 13 | O7: 159629 | S7: =H7*24+I7+J7/60+K7/3600 -> 735.21667
C8: CO2 0.9047% | D8: sample後 | F8: 2013 | G8: 7 | H8: 30 | I8: 15 | J8: 14 | O8: 160195 | S8: =H8*24+I8+J8/60+K8/3600 -> 735.23333
C9: CO2 0.9047% | D9: sample後 | F9: 2013 | G9: 7 | H9: 30 | I9: 15 | J9: 15 | O9: 159386 | S9: =H9*24+I9+J9/60+K9/3600 -> 735.25
C10: CO2 0.9047% | D10: sample後 | F10: 2013 | G10: 7 | H10: 30 | I10: 15 | J10: 16 | O10: 163286 | S10: =H10*24+I10+J10/60+K10/3600 -> 735.26667
F11: 2013 | G11: 7 | H11: 30 | I11: 15 | J11: 16 | O11: 164045 | S11: =H11*24+I11+J11/60+K11/3600 -> 735.26667
B14: 標準パラメータ | Q14: factor
C15: CO2濃度 | D15: CO2 | F15: 9047 | G15: ppm | H15: 前 | M15: =AVERAGE(M2:M6) -> #DIV/0! | N15: =AVERAGE(N2:N6) -> #DIV/0! | O15: =AVERAGE(O2:O11) -> 164809.4 | Q15: =F15/O15 -> 0.054893714 | S15: =AVERAGE(S2:S6) -> 733.11333
H16: 後 | M16: =AVERAGE(M7:M11) -> #DIV/0! | N16: =AVERAGE(N7:N11) -> #DIV/0! | O16: =AVERAGE(O7:O11) -> 161308.2 | Q16: =F15/O16 -> 0.056085184 | S16: =AVERAGE(S7:S11) -> 735.24667
Q18: 初期std利用 | U18: ドリフト補正有
B19: 15 deg | C19: 1 | F19: 2013 | G19: 7 | H19: 30 | I19: 13 | J19: 25 | O19: 23562 | Q19: =O19*$Q$15 -> 1293.4057 | S19: =H19*24+I19+J19/60+K19/3600 -> 733.41667 | T19: =Q15+(Q16-Q15)*(S19-S15)/(S16-S15) -> 0.055063126 | U19: =O19*T19 -> 1297.3974
C20: 2 | F20: 2013 | G20: 7 | H20: 30 | I20: 13 | J20: 26 | O20: 13592 | Q20: =O20*$Q$15 -> 746.11536 | S20: =H20*24+I20+J20/60+K20/3600 -> 733.43333 | T20: =Q15+(Q16-Q15)*(S20-S15)/(S16-S15) -> 0.055072434 | U20: =O20*T20 -> 748.54452
C21: 3 | F21: 2013 | G21: 7 | H21: 30 | I21: 13 | J21: 27 | O21: 24470 | Q21: =O21*$Q$15 -> 1343.2492 | S21: =H21*24+I21+J21/60+K21/3600 -> 733.45 | T21: =Q15+(Q16-Q15)*(S21-S15)/(S16-S15) -> 0.055081742 | U21: =O21*T21 -> 1347.8502
C22: 4 | F22: 2013 | G22: 7 | H22: 30 | I22: 13 | J22: 28 | O22: 14778 | Q22: =O22*$Q$15 -> 811.2193 | S22: =H22*24+I22+J22/60+K22/3600 -> 733.46667 | T22: =Q15+(Q16-Q15)*(S22-S15)/(S16-S15) -> 0.055091051 | U22: =O22*T22 -> 814.13555
C23: 5 | F23: 2013 | G23: 7 | H23: 30 | I23: 13 | J23: 29 | O23: 19824 | Q23: =O23*$Q$15 -> 1088.213 | S23: =H23*24+I23+J23/60+K23/3600 -> 733.48333 | T23: =Q15+(Q16-Q15)*(S23-S15)/(S16-S15) -> 0.055100359 | U23: =O23*T23 -> 1092.3095
C24: 6 | F24: 2013 | G24: 7 | H24: 30 | I24: 13 | J24: 29 | O24: 14858 | Q24: =O24*$Q$15 -> 815.6108 | S24: =H24*24+I24+J24/60+K24/3600 -> 733.48333 | T24: =Q15+(Q16-Q15)*(S24-S15)/(S16-S15) -> 0.055100359 | U24: =O24*T24 -> 818.68114
C25: 7 | F25: 2013 | G25: 7 | H25: 30 | I25: 13 | J25: 30 | O25: 15146 | Q25: =O25*$Q$15 -> 831.42019 | S25: =H25*24+I25+J25/60+K25/3600 -> 733.5 | T25: =Q15+(Q16-Q15)*(S25-S15)/(S16-S15) -> 0.055109668 | U25: =O25*T25 -> 834.69102
C26: 8 | F26: 2013 | G26: 7 | H26: 30 | I26: 13 | J26: 31 | O26: 12677 | Q26: =O26*$Q$15 -> 695.88761 | S26: =H26*24+I26+J26/60+K26/3600 -> 733.51667 | T26: =Q15+(Q16-Q15)*(S26-S15)/(S16-S15) -> 0.055118976 | U26: =O26*T26 -> 698.74326
C27: 9 | F27: 2013 | G27: 7 | H27: 30 | I27: 13 | J27: 32 | O27: 13754 | Q27: =O27*$Q$15 -> 755.00814 | S27: =H27*24+I27+J27/60+K27/3600 -> 733.53333 | T27: =Q15+(Q16-Q15)*(S27-S15)/(S16-S15) -> 0.055128284 | U27: =O27*T27 -> 758.23442
C28: 10 | F28: 2013 | G28: 7 | H28: 30 | I28: 13 | J28: 33 | O28: 21565 | Q28: =O28*$Q$15 -> 1183.7829 | S28: =H28*24+I28+J28/60+K28/3600 -> 733.55 | T28: =Q15+(Q16-Q15)*(S28-S15)/(S16-S15) -> 0.055137593 | U28: =O28*T28 -> 1189.0422
C29: 12 | F29: 2013 | G29: 7 | H29: 30 | I29: 13 | J29: 34 | O29: 13110 | Q29: =O29*$Q$15 -> 719.65659 | S29: =H29*24+I29+J29/60+K29/3600 -> 733.56667 | T29: =Q15+(Q16-Q15)*(S29-S15)/(S16-S15) -> 0.055146901 | U29: =O29*T29 -> 722.97587
C30: 13 | F30: 2013 | G30: 7 | H30: 30 | I30: 13 | J30: 35 | O30: 17200 | Q30: =O30*$Q$15 -> 944.17187 | S30: =H30*24+I30+J30/60+K30/3600 -> 733.58333 | T30: =Q15+(Q16-Q15)*(S30-S15)/(S16-S15) -> 0.055156209 | U30: =O30*T30 -> 948.6868
C31: 14 | F31: 2013 | G31: 7 | H31: 30 | I31: 13 | J31: 36 | O31: 13734 | Q31: =O31*$Q$15 -> 753.91026 | S31: =H31*24+I31+J31/60+K31/3600 -> 733.6 | T31: =Q15+(Q16-Q15)*(S31-S15)/(S16-S15) -> 0.055165518 | U31: =O31*T31 -> 757.64322
C32: 85 | F32: 2013 | G32: 7 | H32: 30 | I32: 13 | J32: 37 | O32: 13539 | Q32: =O32*$Q$15 -> 743.20599 | S32: =H32*24+I32+J32/60+K32/3600 -> 733.61667 | T32: =Q15+(Q16-Q15)*(S32-S15)/(S16-S15) -> 0.055174826 | U32: =O32*T32 -> 747.01197
C33: 15 | F33: 2013 | G33: 7 | H33: 30 | I33: 13 | J33: 38 | O33: 17798 | Q33: =O33*$Q$15 -> 976.99831 | S33: =H33*24+I33+J33/60+K33/3600 -> 733.63333 | T33: =Q15+(Q16-Q15)*(S33-S15)/(S16-S15) -> 0.055184134 | U33: =O33*T33 -> 982.16722
C34: 16 | F34: 2013 | G34: 7 | H34: 30 | I34: 13 | J34: 39 | O34: 59107 | Q34: =O34*$Q$15 -> 3244.6027 | S34: =H34*24+I34+J34/60+K34/3600 -> 733.65 | T34: =Q15+(Q16-Q15)*(S34-S15)/(S16-S15) -> 0.055193443 | U34: =O34*T34 -> 3262.3188
C35: 17 | F35: 2013 | G35: 7 | H35: 30 | I35: 13 | J35: 40 | O35: 212093 | Q35: =O35*$Q$15 -> 11642.572 | S35: =H35*24+I35+J35/60+K35/3600 -> 733.66667 | T35: =Q15+(Q16-Q15)*(S35-S15)/(S16-S15) -> 0.055202751 | U35: =O35*T35 -> 11708.117
C36: 18 | F36: 2013 | G36: 7 | H36: 30 | I36: 13 | J36: 41 | O36: 32410 | P36: ???!!! | Q36: =O36*$Q$15 -> 1779.1053 | S36: =H36*24+I36+J36/60+K36/3600 -> 733.68333 | T36: =Q15+(Q16-Q15)*(S36-S15)/(S16-S15) -> 0.055212059 | U36: =O36*T36 -> 1789.4228
C37: 19 | F37: 2013 | G37: 7 | H37: 30 | I37: 13 | J37: 42 | O37: 27360 | Q37: =O37*$Q$15 -> 1501.892 | S37: =H37*24+I37+J37/60+K37/3600 -> 733.7 | T37: =Q15+(Q16-Q15)*(S37-S15)/(S16-S15) -> 0.055221368 | U37: =O37*T37 -> 1510.8566
C38: 20 | F38: 2013 | G38: 7 | H38: 30 | I38: 13 | J38: 43 | O38: 18573 | Q38: =O38*$Q$15 -> 1019.5409 | S38: =H38*24+I38+J38/60+K38/3600 -> 733.71667 | T38: =Q15+(Q16-Q15)*(S38-S15)/(S16-S15) -> 0.055230676 | U38: =O38*T38 -> 1025.7993
C39: 21 | F39: 2013 | G39: 7 | H39: 30 | I39: 13 | J39: 43 | O39: 14224 | Q39: =O39*$Q$15 -> 780.80818 | S39: =H39*24+I39+J39/60+K39/3600 -> 733.71667 | T39: =Q15+(Q16-Q15)*(S39-S15)/(S16-S15) -> 0.055230676 | U39: =O39*T39 -> 785.60114
C40: 22 | F40: 2013 | G40: 7 | H40: 30 | I40: 13 | J40: 44 | O40: 16427 | Q40: =O40*$Q$15 -> 901.73903 | S40: =H40*24+I40+J40/60+K40/3600 -> 733.73333 | T40: =Q15+(Q16-Q15)*(S40-S15)/(S16-S15) -> 0.055239985 | U40: =O40*T40 -> 907.42723
C41: 23 | F41: 2013 | G41: 7 | H41: 30 | I41: 13 | J41: 46 | O41: 16040 | Q41: =O41*$Q$15 -> 880.49517 | S41: =H41*24+I41+J41/60+K41/3600 -> 733.76667 | T41: =Q15+(Q16-Q15)*(S41-S15)/(S16-S15) -> 0.055258601 | U41: =O41*T41 -> 886.34796
C42: 24 | F42: 2013 | G42: 7 | H42: 30 | I42: 13 | J42: 46 | O42: 20150 | Q42: =O42*$Q$15 -> 1106.1083 | S42: =H42*24+I42+J42/60+K42/3600 -> 733.76667 | T42: =Q15+(Q16-Q15)*(S42-S15)/(S16-S15) -> 0.055258601 | U42: =O42*T42 -> 1113.4608
C43: 25 | F43: 2013 | G43: 7 | H43: 30 | I43: 13 | J43: 48 | O43: 17139 | Q43: =O43*$Q$15 -> 940.82336 | S43: =H43*24+I43+J43/60+K43/3600 -> 733.8 | T43: =Q15+(Q16-Q15)*(S43-S15)/(S16-S15) -> 0.055277218 | U43: =O43*T43 -> 947.39624
...

Sheet 8-1-13 Final #1
B1: 区・条件 | C1: STD ppm | F1: year | G1: month | H1: day | I1: hh | J1: mm | K1: ss | L1: sample number | M1: CO2rt | N1: CO2hi | O1: CO2area | P1: 右は計算領域 | Q1: CO2(ppm)初期標準 | R1: ドリフト時計算 | S1: 絶対時間（ｈ） | T1: ドリフトstd factor | U1: CO2(ppm) | X1: 41487
C2: CO2 0.9047% | D2: sample前 | F2: 2013 | G2: 8 | H2: 32 | I2: 11 | J2: 20 | O2: 170076 | S2: =H2*24+I2+J2/60+K2/3600 -> 779.33333 | X2: had to enter date as 8/32 for formulae in column S
B3: CO２ | C3: CO2 0.9047% | D3: sample前 | F3: 2013 | G3: 8 | H3: 32 | I3: 11 | J3: 21 | O3: 168517 | S3: =H3*24+I3+J3/60+K3/3600 -> 779.35
B4: 9047 | C4: CO2 0.9047% | D4: sample前 | F4: 2013 | G4: 8 | H4: 32 | I4: 11 | J4: 22 | O4: 175690 | S4: =H4*24+I4+J4/60+K4/3600 -> 779.36667
C5: CO2 0.9047% | D5: sample前 | F5: 2013 | G5: 8 | H5: 32 | I5: 11 | J5: 23 | O5: 173206 | S5: =H5*24+I5+J5/60+K5/3600 -> 779.38333
C7: CO2 0.9047% | D7: sample後 | F7: 2013 | G7: 8 | H7: 32 | I7: 12 | J7: 53 | O7: 171046 | S7: =H7*24+I7+J7/60+K7/3600 -> 780.88333
C8: CO2 0.9047% | D8: sample後 | F8: 2013 | G8: 8 | H8: 32 | I8: 12 | J8: 54 | O8: 198926 | S8: =H8*24+I8+J8/60+K8/3600 -> 780.9
C9: CO2 0.9047% | D9: sample後 | F9: 2013 | G9: 8 | H9: 32 | I9: 12 | J9: 55 | O9: 188090 | S9: =H9*24+I9+J9/60+K9/3600 -> 780.91667
C10: CO2 0.9047% | D10: sample後 | F10: 2013 | G10: 8 | H10: 32 | I10: 12 | J10: 56 | O10: 177491 | S10: =H10*24+I10+J10/60+K10/3600 -> 780.93333
B14: 標準パラメータ | Q14: factor
C15: CO2濃度 | D15: CO2 | F15: 9047 | G15: ppm | H15: 前 | M15: =AVERAGE(M2:M6) -> #DIV/0! | N15: =AVERAGE(N2:N6) -> #DIV/0! | O15: =AVERAGE(O2:O6) -> 171872.25 | Q15: =F15/O15 -> 0.052637933 | S15: =AVERAGE(S2:S6) -> 779.35833
H16: 後 | M16: =AVERAGE(M7:M11) -> #DIV/0! | N16: =AVERAGE(N7:N11) -> #DIV/0! | O16: =AVERAGE(O7:O11) -> 183888.25 | Q16: =F15/O16 -> 0.049198358 | S16: =AVERAGE(S7:S11) -> 780.90833
Q18: 初期std利用 | U18: ドリフト補正有
B19: 15 deg | C19: 1 | F19: 2013 | G19: 8 | H19: 32 | I19: 11 | J19: 25 | O19: 88219 | Q19: =O19*$Q$15 -> 4643.6658 | S19: =H19*24+I19+J19/60+K19/3600 -> 779.41667 | T19: =Q15+(Q16-Q15)*(S19-S15)/(S16-S15) -> 0.052508487 | U19: =O19*T19 -> 4632.2462
C20: 2 | F20: 2013 | G20: 8 | H20: 32 | I20: 11 | J20: 26 | O20: 51312 | Q20: =O20*$Q$15 -> 2700.9576 | S20: =H20*24+I20+J20/60+K20/3600 -> 779.43333 | T20: =Q15+(Q16-Q15)*(S20-S15)/(S16-S15) -> 0.052471502 | U20: =O20*T20 -> 2692.4177
C21: 3 | F21: 2013 | G21: 8 | H21: 32 | I21: 11 | J21: 27 | O21: 70566 | Q21: =O21*$Q$15 -> 3714.4484 | S21: =H21*24+I21+J21/60+K21/3600 -> 779.45 | T21: =Q15+(Q16-Q15)*(S21-S15)/(S16-S15) -> 0.052434517 | U21: =O21*T21 -> 3700.0942
C22: 4 | F22: 2013 | G22: 8 | H22: 32 | I22: 11 | J22: 28 | O22: 54752 | Q22: =O22*$Q$15 -> 2882.0321 | S22: =H22*24+I22+J22/60+K22/3600 -> 779.46667 | T22: =Q15+(Q16-Q15)*(S22-S15)/(S16-S15) -> 0.052397533 | U22: =O22*T22 -> 2868.8697
C23: 5 | F23: 2013 | G23: 8 | H23: 32 | I23: 11 | J23: 29 | O23: 81312 | Q23: =O23*$Q$15 -> 4280.0956 | S23: =H23*24+I23+J23/60+K23/3600 -> 779.48333 | T23: =Q15+(Q16-Q15)*(S23-S15)/(S16-S15) -> 0.052360548 | U23: =O23*T23 -> 4257.5409
C24: 6 | F24: 2013 | G24: 8 | H24: 32 | I24: 11 | J24: 29 | O24: 36870 | Q24: =O24*$Q$15 -> 1940.7606 | S24: =H24*24+I24+J24/60+K24/3600 -> 779.48333 | T24: =Q15+(Q16-Q15)*(S24-S15)/(S16-S15) -> 0.052360548 | U24: =O24*T24 -> 1930.5334
C25: 7 | F25: 2013 | G25: 8 | H25: 32 | I25: 11 | J25: 30 | O25: 43398 | Q25: =O25*$Q$15 -> 2284.381 | S25: =H25*24+I25+J25/60+K25/3600 -> 779.5 | T25: =Q15+(Q16-Q15)*(S25-S15)/(S16-S15) -> 0.052323563 | U25: =O25*T25 -> 2270.738
C26: 8 | F26: 2013 | G26: 8 | H26: 32 | I26: 11 | J26: 31 | O26: 33571 | Q26: =O26*$Q$15 -> 1767.1081 | S26: =H26*24+I26+J26/60+K26/3600 -> 779.51667 | T26: =Q15+(Q16-Q15)*(S26-S15)/(S16-S15) -> 0.052286579 | U26: =O26*T26 -> 1755.3127
